Workbook

Sheet Tabela de Valores de Receitas
H2: Doce Lua | J2: Confeitaria Artesanal | R2: Bolo | S2: 750 | T2: g
H3: Tabela de Valores de Receitas | R3: =J22/3 -> 3.3428889 | S3: =S2/2 -> 375 | T3: g | U3: = | V3: 1.1/2 Bolo de pote
F4: Receita | I4: Rendimento | J4: Ingrediente | K4: Quantidade | M4: Medida | N4: Valor Unitário | O4: Valor total por ingrediente | R4: =R3*2 -> 6.6857778 | S4: Forma 20cm
F5: Bolo de Cenoura | I5: 8 porções | J5: Cenoura | K5: 3 | M5: Unidade | N5: {=_xlfn.IFS(M5='Tabela de Valores de materiais'!K3,'Tabela de Valores de materiais'!K6,'Tabela de Valores de Receitas'!M5='Tabela de Valores de materiais'!J3,'Tabela de Valores de materiais'!J6,'Tabela de Valores de Receitas'!M5='Tabela de Valores de materiais'!I3,'Tabela de Valores de materiais'!I6,'Tabela de Valores de Receitas'!M5='Tabela de Valores de materiais'!H3,'Tabela de Valores de materiais'!H6)} -> 1.68 | O5: =N5*K5 -> 5.04 | R5: =O22/3 -> 5.0128889 | V5: =S3/3 -> 125 | W5: =V5*2 -> 250
F6: Valor para produção | J6: Açúcar | K6: 2 | M6: Xícara | N6: {=_xlfn.IFS(M6="XÍCARA",'Tabela de Valores de materiais'!H4,'Tabela de Valores de Receitas'!$M$6='Tabela de Valores de materiais'!I3,'Tabela de Valores de materiais'!I4,'Tabela de Valores de Receitas'!$M$6='Tabela de Valores de materiais'!J3,'Tabela de Valores de materiais'!J4)} -> 0.8 | O6: =N6*K6 -> 1.6 | R6: =R5*2 -> 10.025778
J7: Fermento em pó | K7: 1 | M7: Colher de chá | N7: {=_xlfn.IFS(M7='Tabela de Valores de materiais'!H3,'Tabela de Valores de materiais'!H5,'Tabela de Valores de Receitas'!M7='Tabela de Valores de materiais'!I3,'Tabela de Valores de materiais'!I5,'Tabela de Valores de Receitas'!M7='Tabela de Valores de materiais'!J3,'Tabela de Valores de materiais'!J5,'Tabela de Valores de Receitas'!M7='Tabela de Valores de materiais'!K3,'Tabela de Valores de materiais'!K5)} -> 0.175 | O7: =N7*K7 -> 0.175
O8: =N8*K8 -> 0
C10: =MID(A13,2,2) -> 82 | D10: {=_xlfn.IFS(A13>999,C14,A13<999,C11)} -> 2,82 | E10: 0 | F10: =J14+D10 -> 7.780658 | H10: Receita: | I10: Bolo 750g (Forma de 20cm) | M10: Porcentagem lucro: | O10: =O21 -> 50 | P10: %
A11: , | C11: =_xlfn.CONCAT(A14,A11,C10) -> 2,82 | D11: =RIGHT(C11,1) -> 2 | E11: =_xlfn.CONCAT(E10,D13,D14) -> 028 | H11: Valor total para produção: | J11: =R4 -> 6.6857778 | M11: Valor para venda: | O11: =R6 -> 10.025778
A12: =F$13 -> 3.921158 | C12: =LEFT(A13,2) -> 28 | E12: =SUM(J14+E14) -> 232.96066
A13: =A12*O13 -> 282.32337 | C13: =MID(A13,3,2) -> 2, | D13: =MID(D10,1,1) -> 2 | F13: =F14+J53 -> 3.921158 | H13: Receita: | I13: Bolo de Pote (Aprox. 210g) | M13: Porcentagem lucro: | O13: 72 | P13: %
A14: =LEFT(A13,1) -> 2 | C14: =_xlfn.CONCAT(C12,A11,C13) -> 28,2, | D14: =MID(D10,3,1) -> 8 | E14: =_xlfn.CONCAT(E10,D11,D13,D14) -> 0228 | F14: =J$22/6 -> 1.6714444 | H14: Valor total para produção: | J14: =H18+I17 -> 4.960658 | M14: Valor para venda: | O14: =IF(D11=",",E12,F10) -> 7.780658
H15: Valor total embalagens: | J15: Material | K15: Quantidade | N15: Valor Unitário | O15: Valor total/ingrediente
I17: =SUM(O17:P19) -> 1.0395 | J17: ='Tabela de Valores de materiais'!B30 -> Folha A4 Adesivo Logotipo | K17: 1 | M17: Unidade | N17: ='Tabela de Valores de materiais'!K30 -> 0.2 | O17: =N17*K17 -> 0.2
H18: =F13 -> 3.921158 | J18: ='Tabela de Valores de materiais'!B12 -> Pote c/ tampa 250ml | K18: 1 | M18: Unidade | N18: ='Tabela de Valores de materiais'!K12 -> 0.6495 | O18: =N18*K18 -> 0.6495
H19: =IF(D11=",",E12,F10) -> 7.780658 | J19: ='Tabela de Valores de materiais'!B11 -> Colher Forte | K19: 1 | M19: Unidade | N19: ='Tabela de Valores de materiais'!K11 -> 0.19 | O19: =N19*K19 -> 0.19
H21: Receita: | I21: Bolo sem cobertura (Forma de 24cm) | M21: Porcentagem lucro: | O21: 50 | P21: %
H22: Valor total para produção: | J22: =SUM(O25:O29) -> 10.028667 | M22: Valor para venda: | O22: =IF(D26=",",E27,F25) -> 15.038667
H23: Sabor: | I23: Rendimento | J23: Ingrediente | K23: Quantidade | N23: Valor Unitário | O23: Valor total/ingrediente
C25: =MID(A28,2,2) -> 01 | D25: {=_xlfn.IFS(A28>999,C29,A28<999,C26)} -> 5,01 | E25: 0 | F25: =J22+D25 -> 15.038667 | H25: Todos | I25: 1 Bolo - Aprox. 750g. + 1 Bolo de pote (210g) OU 1 Bolo - Aprox. 830g OU 6 Bolos de pote (210g) | J25: Ovo | K25: 2 | M25: Unidade | N25: ='Tabela de Valores de materiais'!K7 -> 0.74 | O25: =N25*K25 -> 1.48
A26: , | C26: =_xlfn.CONCAT(A29,A26,C25) -> 5,01 | D26: =RIGHT(C26,1) -> 1 | E26: =_xlfn.CONCAT(E25,D28,D29) -> 050 | J26: Leite | K26: 1 | M26: Xícara | N26: {=_xlfn.IFS('Tabela de Valores de Receitas'!M26='Tabela de Valores de materiais'!H3,'Tabela de Valores de materiais'!H8,'Tabela de Valores de Receitas'!M26='Tabela de Valores de materiais'!I3,'Tabela de Valores de materiais'!I8,'Tabela de Valores de Receitas'!M26='Tabela de Valores de materiais'!J3,'Tabela de Valores de materiais'!J8,'Tabela de Valores de Receitas'!M26='Tabela de Valores de materiais'!K3,'Tabela de Valores de materiais'!K8)} -> 0.792 | O26: =N26*K26 -> 0.792
A27: =J$22 -> 10.028667 | C27: =LEFT(A28,2) -> 50 | E27: =SUM(J22+E29) -> 160.02867 | J27: Óleo | K27: 3 | M27: Colher de Sopa | N27: {=_xlfn.IFS('Tabela de Valores de Receitas'!M27='Tabela de Valores de materiais'!H3,'Tabela de Valores de materiais'!H10,'Tabela de Valores de Receitas'!M27='Tabela de Valores de materiais'!I3,'Tabela de Valores de materiais'!I10,'Tabela de Valores de Receitas'!M27='Tabela de Valores de materiais'!J3,'Tabela de Valores de materiais'!J10,'Tabela de Valores de Receitas'!M27='Tabela de Valores de materiais'!K3,'Tabela de Valores de materiais'!K10)} -> 0.088888889 | O27: =N27*K27 -> 0.26666667
A28: =A27*O21 -> 501.43333 | C28: =MID(A28,3,2) -> 1, | D28: =MID(D25,1,1) -> 5 | J28: Massa semi-pronta | K28: 1 | M28: Unidade | N28: ='Tabela de Valores de materiais'!K9 -> 5.89 | O28: =N28*K28 -> 5.89
A29: =LEFT(A28,1) -> 5 | C29: =_xlfn.CONCAT(C27,A26,C28) -> 50,1, | D29: =MID(D25,3,1) -> 0 | E29: =_xlfn.CONCAT(E25,D26,D28,D29) -> 0150 | J29: Bandeja com Tampa | K29: 1 | M29: Unidade | N29: ='Tabela de Valores de materiais'!K15 -> 1.6 | O29: =N29*K29 -> 1.6
H31: Receita: | I31: Cobertura Ganache p/bolo 750g | M31: Porcentagem lucro: | O31: 5 | P31: %
H32: Valor total para produção: | J32: =SUM(O35:O37) -> 6.9337524 | M32: Valor para venda: | O32: =IF(D36=",",E37,F35) -> 7.2737524
H33: Sabor: | I33: Rendimento | J33: Ingrediente | K33: Quantidade | N33: Valor Unitário | O33: Valor total/ingrediente
C35: =MID(A38,2,2) -> 4, | D35: {=_xlfn.IFS(A38>999,C39,A38<999,C36)} -> 3,4, | E35: 0 | F35: =J32+D35 -> #VALUE! | H35: Ganache Chocolate | I35: Aproximadamente. 150ml | J35: Barra de Chocolate | K35: 1 | M35: Unidade | N35: ='Tabela de Valores de materiais'!K18 -> 6 | O35: =N35*K35 -> 6
A36: , | C36: =_xlfn.CONCAT(A39,A36,C35) -> 3,4, | D36: =RIGHT(C36,1) -> , | E36: =_xlfn.CONCAT(E35,D38,D39) -> 034 | J36: Creme de Leite | K36: 3 | M36: Colher de Sopa | N36: {=_xlfn.IFS(M36=Tabela1[[#Headers],[Xícara]],'Tabela de Valores de materiais'!H19,'Tabela de Valores de Receitas'!M36=Tabela1[[#Headers],[Colher de Sopa]],'Tabela de Valores de materiais'!I19,'Tabela de Valores de Receitas'!M36=Tabela1[[#Headers],[Colher de chá]],'Tabela de Valores de materiais'!J19,'Tabela de Valores de Receitas'!M36=Tabela1[[#Headers],[Unidade]],'Tabela de Valores de materiais'!K19)} -> 0.1845 | O36: =N36*K36 -> 0.5535
A37: =J$32 -> 6.9337524 | C37: =LEFT(A38,2) -> 34 | E37: =SUM(J32+E39) -> 7.2737524 | J37: Receita Brigadeiro | K37: 2 | M37: Colher de Sopa | N37: =P39 -> 0.19012622 | O37: =O39 -> 0.38025244
A38: =A37*O31 -> 34.668762 | C38: =MID(A38,3,2) -> ,6 | D38: =MID(D35,1,1) -> 3 | J38: =O45 -> 6.95 | K38: =O46 -> 0.369 | L38: =O47 -> 0.5712381 | M38: 395 | N38: 10 | O38: 10 | P38: =N38*K37 -> 20
A39: =LEFT(A38,1) -> 3 | C39: =_xlfn.CONCAT(C37,A36,C38) -> 34,,6 | D39: =MID(D35,3,1) -> 4 | E39: =_xlfn.CONCAT(E35,D36,D38,D39) -> 0,34 | J39: =SUM(J38:L38) -> 7.8902381 | M39: =SUM(M38:O38) -> 415 | N39: =J39/M39 -> 0.019012622 | O39: =N39*P38 -> 0.38025244 | P39: =N39*N38 -> 0.19012622
H41: Receita: | I41: Brigadeiro | M41: Porcentagem lucro: | O41: 0 | P41: %
H42: Valor total para produção: | J42: =SUM(O45:O50) -> 8.9988541 | M42: Valor para venda: | O42: =IF(D46=",",E47,F45) -> 8.9988541
H43: Sabor: | I43: Rendimento | J43: Ingrediente | K43: Quantidade | N43: Valor Unitário | O43: Valor total/ingrediente
C45: =MID(A48,2,2) | D45: {=_xlfn.IFS(A48>999,C49,A48<999,C46)} -> 0, | E45: 0 | F45: =J42+D45 -> 8.9988541 | H45: Chocolate | I45: 4 Unidades de Bolo de pote 210g (840g) | J45: Leite Condensado | K45: 1 | M45: Unidade | N45: ='Tabela de Valores de materiais'!K13 -> 6.95 | O45: =N45*K45 -> 6.95
A46: , | C46: =_xlfn.CONCAT(A49,A46,C45) -> 0, | D46: =RIGHT(C46,1) -> , | E46: =_xlfn.CONCAT(E45,D48,D49) -> 00 | J46: Creme de Leite | K46: 2 | M46: Colher de Sopa | N46: {=_xlfn.IFS(M36=Tabela1[[#Headers],[Xícara]],'Tabela de Valores de materiais'!H19,'Tabela de Valores de Receitas'!M36=Tabela1[[#Headers],[Colher de Sopa]],'Tabela de Valores de materiais'!I19,'Tabela de Valores de Receitas'!M36=Tabela1[[#Headers],[Colher de chá]],'Tabela de Valores de materiais'!J19,'Tabela de Valores de Receitas'!M36=Tabela1[[#Headers],[Unidade]],'Tabela de Valores de materiais'!K19)} -> 0.1845 | O46: =N46*K46 -> 0.369
A47: =J$42 -> 8.9988541 | C47: =LEFT(A48,2) -> 0 | E47: =SUM(J42+E49) -> 8.9988541 | J47: Cacau em pó | K47: 2 | M47: Colher de Sopa | N47: {=_xlfn.IFS(M47=Tabela1[[#Headers],[Xícara]],'Tabela de Valores de materiais'!H14,'Tabela de Valores de Receitas'!M47=Tabela1[[#Headers],[Colher de Sopa]],'Tabela de Valores de materiais'!I14,'Tabela de Valores de Receitas'!M47=Tabela1[[#Headers],[Colher de chá]],'Tabela de Valores de materiais'!J14,'Tabela de Valores de Receitas'!M47=Tabela1[[#Headers],[Unidade]],'Tabela de Valores de materiais'!K14)} -> 0.28561905 | O47: =N47*K47 -> 0.5712381
A48: =A47*O41 -> 0 | C48: =MID(A48,3,2) | D48: =MID(D45,1,1) -> 0 | J48: Leite | K48: 0.5 | M48: Xícara | N48: {=_xlfn.IFS(M48=Tabela1[[#Headers],[Xícara]],'Tabela de Valores de materiais'!H8,'Tabela de Valores de Receitas'!M48=Tabela1[[#Headers],[Colher de Sopa]],'Tabela de Valores de materiais'!I8,'Tabela de Valores de Receitas'!M48=Tabela1[[#Headers],[Colher de chá]],'Tabela de Valores de materiais'!J8,'Tabela de Valores de Receitas'!M48=Tabela1[[#Headers],[Unidade]],'Tabela de Valores de materiais'!K8)} -> 0.792 | O48: =N48*K48 -> 0.396
A49: =LEFT(A48,1) -> 0 | C49: =_xlfn.CONCAT(C47,A46,C48) -> 0, | D49: =MID(D45,3,1) | E49: =_xlfn.CONCAT(E45,D46,D48,D49) -> 0,0 | J49: Confeito | K49: 4 | M49: Colher de chá | N49: {=_xlfn.IFS(M49=Tabela1[[#Headers],[Xícara]],'Tabela de Valores de materiais'!H17,'Tabela de Valores de Receitas'!M49=Tabela1[[#Headers],[Colher de Sopa]],'Tabela de Valores de materiais'!I17,'Tabela de Valores de Receitas'!M49=Tabela1[[#Headers],[Colher de chá]],'Tabela de Valores de materiais'!J17,'Tabela de Valores de Receitas'!M49=Tabela1[[#Headers],[Unidade]],'Tabela de Valores de materiais'!K17)} -> 0.13416667 | O49: =N49*K49 -> 0.53666667
...

Sheet Tabela de Valores de materiais
B2: Tabela de Materiais de Consumo | H2: Tabela Automática de Cálculos Fracionados
B3: Ingrediente | C3: Unidade por pacote | D3: Medida em Gramas/ml | E3: Valor Pago na NF mais recente | F3: Valor 1 grama | H3: Xícara | I3: Colher de Sopa | J3: Colher de chá | K3: Unidade | M3: Medida | N3: Gramas/ml
B4: Açúcar | C4: 1 | D4: 1000 | E4: 5 | F4: =E4/D4 -> 0.005 | H4: =F4*$N$4 -> 0.8 | I4: =F4*$N$5 -> 0.05 | J4: =F4*$N$6 -> 0.0175 | K4: =E4/C4 -> 5 | M4: Xícara | N4: 160
B5: Fermento em pó | C5: 1 | D5: 100 | E5: 5 | F5: =E5/D5 -> 0.05 | H5: =F5*$N$4 -> 8 | I5: =F5*$N$5 -> 0.5 | J5: =F5*$N$6 -> 0.175 | K5: =E5/C5 -> 5 | M5: Colher de Sopa | N5: 10
B6: Cenoura | C6: 1 | D6: X | E6: 1.68 | F6: =IFERROR(E6/D6,"0") -> 0 | H6: =F6*$N$4 -> 0 | I6: =F6*$N$5 -> 0 | J6: =F6*$N$6 -> 0 | K6: =E6/C6 -> 1.68 | M6: Colher de chá | N6: 3.5
B7: Ovo | C7: 1 | D7: X | E7: 0.74 | F7: =IFERROR(E7/D7,"0") -> 0 | H7: =F7*$N$4 -> 0 | I7: =F7*$N$5 -> 0 | J7: =F7*$N$6 -> 0 | K7: =E7/C7 -> 0.74 | N7: 1
B8: Leite | C8: 1 | D8: 1000 | E8: 4.95 | F8: =IFERROR(E8/D8,"0") -> 0.00495 | H8: =F8*$N$4 -> 0.792 | I8: =F8*$N$5 -> 0.0495 | J8: =F8*$N$6 -> 0.017325 | K8: =E8/C8 -> 4.95 | M8: 40gotas fracionadas | N8: 0.01
B9: Massa Semi-Pronta | C9: 1 | D9: X | E9: 5.89 | F9: =IFERROR(E9/D9,"0") -> 0 | H9: =F9*$N$4 -> 0 | I9: =F9*$N$5 -> 0 | J9: =F9*$N$6 -> 0 | K9: =E9/C9 -> 5.89
B10: Óleo | C10: 1 | D10: 900 | E10: 8 | F10: =IFERROR(E10/D10,"0") -> 0.0088888889 | H10: =F10*$N$4 -> 1.4222222 | I10: =F10*$N$5 -> 0.088888889 | J10: =F10*$N$6 -> 0.031111111 | K10: =E10/C10 -> 8
B11: Colher Forte | C11: 20 | D11: X | E11: 3.8 | F11: =IFERROR(E11/D11,"0") -> 0 | H11: =F11*$N$4 -> 0 | I11: =F11*$N$5 -> 0 | J11: =F11*$N$6 -> 0 | K11: =E11/C11 -> 0.19
B12: Pote c/ tampa 250ml | C12: 20 | D12: X | E12: 12.99 | F12: =IFERROR(E12/D12,"0") -> 0 | H12: =F12*$N$4 -> 0 | I12: =F12*$N$5 -> 0 | J12: =F12*$N$6 -> 0 | K12: =E12/C12 -> 0.6495
B13: Leite Condensado Piracanjuba | C13: 1 | D13: 395 | E13: 6.95 | F13: =IFERROR(E13/D13,"0") -> 0.017594937 | H13: =F13*$N$4 -> 2.8151899 | I13: =F13*$N$5 -> 0.17594937 | J13: =F13*$N$6 -> 0.061582278 | K13: =E13/C13 -> 6.95
B14: Cacau em Po 50% | C14: 1 | D14: 1050 | E14: 29.99 | F14: =IFERROR(E14/D14,"0") -> 0.028561905 | H14: =F14*$N$4 -> 4.5699048 | I14: =F14*$N$5 -> 0.28561905 | J14: =F14*$N$6 -> 0.099966667 | K14: =E14/C14 -> 29.99
B15: Bandeja c/ Tampa | C15: 1 | D15: X | E15: 1.6 | F15: =IFERROR(E15/D15,"0") -> 0 | H15: =F15*$N$4 -> 0 | I15: =F15*$N$5 -> 0 | J15: =F15*$N$6 -> 0 | K15: =E15/C15 -> 1.6
B16: Cobertura Chocolate Fracionado (Gotas) | C16: 1 | D16: 333 | E16: 8.99 | F16: =IFERROR(E16/D16,"0") -> 0.026996997 | H16: =F16*$N$4 -> 4.3195195 | I16: =F16*$N$5 -> 0.26996997 | J16: =F16*$N$6 -> 0.094489489 | K16: =E16/C16 -> 8.99 | M16: =F16*$N$8 -> 0.00026996997
B17: Flocos Chocolate | C17: 1 | D17: 150 | E17: 5.75 | F17: =IFERROR(E17/D17,"0") -> 0.038333333 | H17: =F17*$N$4 -> 6.1333333 | I17: =F17*$N$5 -> 0.38333333 | J17: =F17*$N$6 -> 0.13416667 | K17: =E17/C17 -> 5.75
B18: Barra Chocolate | C18: 1 | D18: 90 | E18: 6 | F18: =IFERROR(E18/D18,"0") -> 0.066666667 | H18: =F18*$N$4 -> 10.666667 | I18: =F18*$N$5 -> 0.66666667 | J18: =F18*$N$6 -> 0.23333333 | K18: =E18/C18 -> 6
B19: Creme de Leite | C19: 1 | D19: 200 | E19: 3.69 | F19: =IFERROR(E19/D19,"0") -> 0.01845 | H19: =F19*$N$4 -> 2.952 | I19: =F19*$N$5 -> 0.1845 | J19: =F19*$N$6 -> 0.064575 | K19: =E19/C19 -> 3.69
B20: Coco Ralado | C20: 1 | D20: 200 | E20: 4.4 | F20: =IFERROR(E20/D20,"0") -> 0.022 | H20: =F20*$N$4 -> 3.52 | I20: =F20*$N$5 -> 0.22 | J20: =F20*$N$6 -> 0.077 | K20: =E20/C20 -> 4.4
B21: Granulado Rosa | C21: 1 | D21: 150 | E21: 3.5 | F21: =IFERROR(E21/D21,"0") -> 0.023333333 | H21: =F21*$N$4 -> 3.7333333 | I21: =F21*$N$5 -> 0.23333333 | J21: =F21*$N$6 -> 0.081666667 | K21: =E21/C21 -> 3.5
B22: Chocolate ao Leite Fracionado (Moeda) | C22: 1 | D22: 500 | E22: 16.99 | F22: =IFERROR(E22/D22,"0") -> 0.03398 | H22: =F22*$N$4 -> 5.4368 | I22: =F22*$N$5 -> 0.3398 | J22: =F22*$N$6 -> 0.11893 | K22: =E22/C22 -> 16.99
B23: Chocolate Branco Fracionado | C23: 1 | D23: 500 | E23: 19.99 | F23: =IFERROR(E23/D23,"0") -> 0.03998 | H23: =F23*$N$4 -> 6.3968 | I23: =F23*$N$5 -> 0.3998 | J23: =F23*$N$6 -> 0.13993 | K23: =E23/C23 -> 19.99
B24: Corante em Gel Rosa | C24: 1 | D24: 50 | E24: 8.5 | F24: =IFERROR(E24/D24,"0") -> 0.17 | H24: =F24*$N$4 -> 27.2 | I24: =F24*$N$5 -> 1.7 | J24: =F24*$N$6 -> 0.595 | K24: =E24/C24 -> 8.5
B25: Laranjas | C25: 7 | D25: X | E25: 4.01 | F25: =IFERROR(E25/D25,"0") -> 0 | H25: =F25*$N$4 -> 0 | I25: =F25*$N$5 -> 0 | J25: =F25*$N$6 -> 0 | K25: =E25/C25 -> 0.57285714
B26: Fermento Biologico | C26: 1 | D26: 10 | E26: 2.5 | F26: =IFERROR(E26/D26,"0") -> 0.25 | H26: =F26*$N$4 -> 40 | I26: =F26*$N$5 -> 2.5 | J26: =F26*$N$6 -> 0.875 | K26: =E26/C26 -> 2.5
B27: Farinha de Trigo | C27: 1 | D27: 1000 | E27: 6 | F27: =IFERROR(E27/D27,"0") -> 0.006 | H27: =F27*$N$4 -> 0.96 | I27: =F27*$N$5 -> 0.06 | J27: =F27*$N$6 -> 0.021 | K27: =E27/C27 -> 6
B28: Margarina | C28: 1 | D28: 500 | E28: 6.35 | F28: =IFERROR(E28/D28,"0") -> 0.0127 | H28: =F28*$N$4 -> 2.032 | I28: =F28*$N$5 -> 0.127 | J28: =F28*$N$6 -> 0.04445 | K28: =E28/C28 -> 6.35
B29: Gas (50cent./hora) | C29: 1 | F29: =IFERROR(E29/D29,"0") -> 0 | H29: =F29*$N$4 -> 0 | I29: =F29*$N$5 -> 0 | J29: =F29*$N$6 -> 0 | K29: =E29/C29 -> 0
B30: Folha A4 Adesivo Logotipo | C30: 20 | D30: X | E30: 4 | F30: =IFERROR(E30/D30,"0") -> 0 | H30: =F30*$N$4 -> 0 | I30: =F30*$N$5 -> 0 | J30: =F30*$N$6 -> 0 | K30: =E30/C30 -> 0.2
B31: Embalagem Brigadeiro | C31: 10 | E31: 4 | F31: =IFERROR(E31/D31,"0") -> 0 | H31: =F31*$N$4 -> 0 | I31: =F31*$N$5 -> 0 | J31: =F31*$N$6 -> 0 | K31: =E31/C31 -> 0.4
B32: Achocolatado | C32: 1 | D32: 200 | E32: 8.5 | F32: =IFERROR(E32/D32,"0") -> 0.0425 | H32: =F32*$N$4 -> 6.8 | I32: =F32*$N$5 -> 0.425 | J32: =F32*$N$6 -> 0.14875 | K32: =E32/C32 -> 8.5
B33: Coloretti | C33: 1 | D33: 300 | E33: 10.5 | F33: =IFERROR(E33/D33,"0") -> 0.035 | H33: =F33*$N$4 -> 5.6 | I33: =F33*$N$5 -> 0.35 | J33: =F33*$N$6 -> 0.1225 | K33: =E33/C33 -> 10.5
B34: Sache Capuccino | C34: 1 | E34: 2.95 | F34: =IFERROR(E34/D34,"0") -> 0 | H34: =F34*$N$4 -> 0 | I34: =F34*$N$5 -> 0 | J34: =F34*$N$6 -> 0 | K34: =E34/C34 -> 2.95
B35: Saco Plástico Transparente | C35: 1 | D35: X | E35: 0.25 | F35: =IFERROR(E35/D35,"0") -> 0 | H35: =F35*$N$4 -> 0 | I35: =F35*$N$5 -> 0 | J35: =F35*$N$6 -> 0 | K35: =E35/C35 -> 0.25
C36: 1 | F36: =IFERROR(E36/D36,"0") -> 0 | H36: =F36*$N$4 -> 0 | I36: =F36*$N$5 -> 0 | J36: =F36*$N$6 -> 0 | K36: =E36/C36 -> 0
C37: 1 | F37: =IFERROR(E37/D37,"0") -> 0 | H37: =F37*$N$4 -> 0 | I37: =F37*$N$5 -> 0 | J37: =F37*$N$6 -> 0 | K37: =E37/C37 -> 0
C38: 1 | F38: =IFERROR(E38/D38,"0") -> 0 | H38: =F38*$N$4 -> 0 | I38: =F38*$N$5 -> 0 | J38: =F38*$N$6 -> 0 | K38: =E38/C38 -> 0
C39: 1 | F39: =IFERROR(E39/D39,"0") -> 0 | H39: =F39*$N$4 -> 0 | I39: =F39*$N$5 -> 0 | J39: =F39*$N$6 -> 0 | K39: =E39/C39 -> 0
C40: 1 | F40: =IFERROR(E40/D40,"0") -> 0 | H40: =F40*$N$4 -> 0 | I40: =F40*$N$5 -> 0 | J40: =F40*$N$6 -> 0 | K40: =E40/C40 -> 0
C41: 1 | F41: =IFERROR(E41/D41,"0") -> 0 | H41: =F41*$N$4 -> 0 | I41: =F41*$N$5 -> 0 | J41: =F41*$N$6 -> 0 | K41: =E41/C41 -> 0
...

Sheet Cadastro Clientes
A1: Nome | B1: Contato
