Workbook

Sheet Setembro
A1: Planejamento Mensal Káic e Gabi | I1: Mês: | J1: Abril
A2: Data hoje formula | B2: Data formula | C2: Formula pgto ok | G2: Saldo Prévio | H2: Descrição Conta | I2: Valor | J2: Data vencimento | K2: Pago?
A3: =TODAY() -> 45567 | B3: 45017 | C3: =A3-B3 -> 550 | D3: =C3+K3 -> #VALUE! | E3: =IF(10,K3="ok",0) -> TRUE | F3: Dia 1 | G3: =I3 -> 0 | K3: ok | L3: =IF(A3=B3,"➜ Hoje","")
A4: =TODAY() -> 45567 | B4: 45018 | C4: =A4-B4 -> 549 | D4: =C4+K4 -> #VALUE! | E4: =IF(10,K4="ok",0) -> TRUE | F4: Dia 2 | G4: =G3+I4 -> 0 | K4: ok | L4: =IF(A4=B4,"➜ Hoje","")
A5: =TODAY() -> 45567 | B5: 45019 | C5: =A5-B5 -> 548 | D5: =C5+K5 -> #VALUE! | E5: =IF(10,K5="ok",0) -> TRUE | F5: Dia 3 | G5: =G4+I5 -> 0 | K5: ok | L5: =IF(A5=B5,"➜ Hoje","")
A6: =TODAY() -> 45567 | B6: 45020 | C6: =A6-B6 -> 547 | D6: =C6+K6 -> #VALUE! | E6: =IF(10,K6="ok",0) -> TRUE | F6: Dia 4 | G6: =G5+I6 -> 0 | K6: ok | L6: =IF(A6=B6,"➜ Hoje","")
A7: =TODAY() -> 45567 | B7: 45021 | C7: =A7-B7 -> 546 | D7: =C7+K7 -> #VALUE! | E7: =IF(10,K7="ok",0) -> TRUE | F7: Dia 5 | G7: =G6+I7 -> 1000 | H7: Pagamento Recebido Bellocopo | I7: 1000 | J7: Dia 5 | K7: ok | L7: =IF(A7=B7,"➜ Hoje","")
A8: =TODAY() -> 45567 | B8: 45022 | C8: =A8-B8 -> 545 | D8: =C8+K8 -> #VALUE! | E8: =IF(10,K8="ok",0) -> TRUE | F8: Dia 6 | G8: =G7+I8 -> 2700 | H8: Pagamento Recebido CD Medical Care | I8: 1700 | J8: Dia 6 | K8: ok | L8: =IF(A8=B8,"➜ Hoje","")
A9: =TODAY() -> 45567 | B9: 45023 | C9: =A9-B9 -> 544 | D9: =C9+K9 -> #VALUE! | E9: =IF(10,K9="ok",0) -> TRUE | F9: Dia 7 | G9: =G8+I9 -> 2640.4 | H9: Areia Gatíssimo (x4 Unidades) | I9: -59.6 | J9: Dia 6 | K9: ok | L9: =IF(A9=B9,"➜ Hoje","")
A10: =TODAY() -> 45567 | B10: 45024 | C10: =A10-B10 -> 543 | D10: =C10+K10 -> #VALUE! | E10: =IF(10,K10="ok",0) -> TRUE | F10: Dia 8 | G10: =G9+I10 -> 2601.4 | H10: Microsoft | I10: -39 | J10: Dia 6 | K10: ok | L10: =IF(A10=B10,"➜ Hoje","")
A11: =TODAY() -> 45567 | B11: 45025 | C11: =A11-B11 -> 542 | D11: =C11+K11 -> #VALUE! | E11: =IF(10,K11="ok",0) -> TRUE | F11: Dia 9 | G11: =G10+I11 -> 2501.4 | H11: Unhas | I11: -100 | J11: Dia 6 | K11: ok | L11: =IF(A11=B11,"➜ Hoje","")
A12: =TODAY() -> 45567 | B12: 45026 | C12: =A12-B12 -> 541 | D12: =C12+K12 -> #VALUE! | E12: =IF(10,K12="ok",0) -> TRUE | F12: Dia 10 | G12: =G11+I12 -> 2101.4 | H12: Psicóloga | I12: -400 | J12: Dia 7 | K12: ok | L12: =IF(A12=B12,"➜ Hoje","")
A13: =TODAY() -> 45567 | B13: 45027 | C13: =A13-B13 -> 540 | D13: =C13+K13 -> #VALUE! | E13: =IF(10,K13="ok",0) -> TRUE | F13: Dia 11 | G13: =G12+I13 -> 1991.4 | H13: Energia Elétrica (1/4 pagamento) | I13: -110 | J13: Dia 8 | K13: ok | L13: =IF(A13=B13,"➜ Hoje","")
A14: =TODAY() -> 45567 | B14: 45028 | C14: =A14-B14 -> 539 | D14: =C14+K14 -> #VALUE! | E14: =IF(10,K14="ok",0) -> TRUE | F14: Dia 12 | G14: =G13+I14 -> 1991.4 | K14: ok | L14: =IF(A14=B14,"➜ Hoje","")
A15: =TODAY() -> 45567 | B15: 45029 | C15: =A15-B15 -> 538 | D15: =C15+K15 -> #VALUE! | E15: =IF(10,K15="ok",0) -> TRUE | F15: Dia 13 | G15: =G14+I15 -> 1991.4 | K15: ok | L15: =IF(A15=B15,"➜ Hoje","")
A16: =TODAY() -> 45567 | B16: 45030 | C16: =A16-B16 -> 537 | D16: =C16+K16 -> #VALUE! | E16: =IF(10,K16="ok",0) -> TRUE | F16: Dia 14 | G16: =G15+I16 -> 1991.4 | K16: ok | L16: =IF(A16=B16,"➜ Hoje","")
A17: =TODAY() -> 45567 | B17: 45031 | C17: =A17-B17 -> 536 | D17: =C17+K17 -> #VALUE! | E17: =IF(10,K17="ok",0) -> TRUE | F17: Dia 15 | G17: =G16+I17 -> 2131.4 | H17: Pagamento Recebido VA Bellocopo | I17: 140 | J17: Dia 15 | K17: ok | L17: =IF(A17=B17,"➜ Hoje","")
A18: =TODAY() -> 45567 | B18: 45032 | C18: =A18-B18 -> 535 | D18: =C18+K18 -> #VALUE! | E18: =IF(10,K18="ok",0) -> TRUE | F18: Dia 16 | G18: =G17+I18 -> 1991.4 | H18: Alimentação Misturas (Compras Mercado) | I18: -140 | J18: Dia 16 | K18: ok | L18: =IF(A18=B18,"➜ Hoje","")
A19: =TODAY() -> 45567 | B19: 45033 | C19: =A19-B19 -> 534 | D19: =C19+K19 -> #VALUE! | E19: =IF(10,K19="ok",0) -> TRUE | F19: Dia 17 | G19: =G18+I19 -> 1991.4 | K19: ok | L19: =IF(A19=B19,"➜ Hoje","")
A20: =TODAY() -> 45567 | B20: 45034 | C20: =A20-B20 -> 533 | D20: =C20+K20 -> #VALUE! | E20: =IF(10,K20="ok",0) -> TRUE | F20: Dia 18 | G20: =G19+I20 -> 1991.4 | K20: ok | L20: =IF(A20=B20,"➜ Hoje","")
A21: =TODAY() -> 45567 | B21: 45035 | C21: =A21-B21 -> 532 | D21: =C21+K21 -> #VALUE! | E21: =IF(10,K21="ok",0) -> TRUE | F21: Dia 19 | G21: =G20+I21 -> 1631.4 | H21: Geladeira (1/11 Parcelas) | I21: -360 | K21: ok | L21: =IF(A21=B21,"➜ Hoje","")
A22: =TODAY() -> 45567 | B22: 45036 | C22: =A22-B22 -> 531 | D22: =C22+K22 -> #VALUE! | E22: =IF(10,K22="ok",0) -> TRUE | F22: Dia 20 | G22: =G21+I22 -> 2631.4 | H22: Pagamento Recebido Bellocopo | I22: 1000 | J22: Dia 20 | K22: ok | L22: =IF(A22=B22,"➜ Hoje","")
A23: =TODAY() -> 45567 | B23: 45037 | C23: =A23-B23 -> 530 | D23: =C23+K23 -> #VALUE! | E23: =IF(10,K23="ok",0) -> TRUE | F23: Dia 21 | G23: =G22+I23 -> 2631.4 | K23: ok | L23: =IF(A23=B23,"➜ Hoje","")
A24: =TODAY() -> 45567 | B24: 45038 | C24: =A24-B24 -> 529 | D24: =C24+K24 -> #VALUE! | E24: =IF(10,K24="ok",0) -> TRUE | F24: Dia 22 | G24: =G23+I24 -> 2631.4 | K24: ok | L24: =IF(A24=B24,"➜ Hoje","")
A25: =TODAY() -> 45567 | B25: 45039 | C25: =A25-B25 -> 528 | D25: =C25+K25 -> #VALUE! | E25: =IF(10,K25="ok",0) -> TRUE | F25: Dia 23 | G25: 0 | K25: ok | L25: =IF(A25=B25,"➜ Hoje","")
A26: =TODAY() -> 45567 | B26: 45040 | C26: =A26-B26 -> 527 | D26: =C26+K26 -> #VALUE! | E26: =IF(10,K26="ok",0) -> TRUE | F26: Dia 24 | G26: =G25+I26 -> 0 | K26: ok | L26: =IF(A26=B26,"➜ Hoje","")
A27: =TODAY() -> 45567 | B27: 45041 | C27: =A27-B27 -> 526 | D27: =C27+K27 -> #VALUE! | E27: =IF(10,K27="ok",0) -> TRUE | F27: Dia 25 | G27: =G26+I27 -> 0 | K27: ok | L27: =IF(A27=B27,"➜ Hoje","")
A28: =TODAY() -> 45567 | B28: 45042 | C28: =A28-B28 -> 525 | D28: =C28+K28 -> #VALUE! | E28: =IF(10,K28="ok",0) -> TRUE | F28: Dia 26 | G28: =G27+I28 -> -21 | H28: Cartão Bradesco (Cheque especial) | I28: -21 | K28: ok | L28: =IF(A28=B28,"➜ Hoje","")
A29: =TODAY() -> 45567 | B29: 45043 | C29: =A29-B29 -> 524 | D29: =C29+K29 -> #VALUE! | E29: =IF(10,K29="ok",0) -> TRUE | F29: Dia 27 | G29: =G28+I29 -> -66 | H29: Internet Celular Vivo | I29: -45 | J29: Dia 27 | K29: ok | L29: =IF(A29=B29,"➜ Hoje","")
A30: =TODAY() -> 45567 | B30: 45044 | C30: =A30-B30 -> 523 | D30: =C30+K30 -> #VALUE! | E30: =IF(10,K30="ok",0) -> TRUE | F30: Dia 28 | G30: =G29+I30 -> -146 | H30: Cílios | I30: -80 | J30: Dia 28 | K30: ok | L30: =IF(A30=B30,"➜ Hoje","")
A31: =TODAY() -> 45567 | B31: 45045 | C31: =A31-B31 -> 522 | D31: =C31+K31 -> 522 | E31: =IF(10,K31="ok",0) -> FALSE | F31: Dia 29 | G31: =G30+I31 -> -163.45 | H31: HBO | I31: -17.45 | L31: =IF(A31=B31,"➜ Hoje","")
A32: =TODAY() -> 45567 | B32: 45046 | C32: =A32-B32 -> 521 | D32: =C32+K32 -> #VALUE! | E32: =IF(10,K32="ok",0) -> TRUE | F32: Dia 30 | G32: =G31+I32 -> -163.45 | K32: ok | L32: =IF(A32=B32,"➜ Hoje","")
A33: =TODAY() -> 45567 | B33: 45077 | C33: =A33-B33 -> 490 | D33: =C33+K33 -> 490 | E33: =IF(10,K33="ok",0) -> FALSE | F33: Dia 31 | G33: 0 | L33: =IF(A33=B33,"➜ Hoje","")

Sheet Maio
A1: Planejamento Mensal Káic e Gabi | I1: Mês: | J1: Maio | M1: Resumo Finalização do Mês | S1: 0
A2: Data hoje formula | B2: Data formula | C2: Formula pgto ok | G2: Saldo Prévio | H2: Descrição Conta | I2: Valor | J2: Data vencimento | K2: Pago? | M2: =F33 -> Dia 31 | N2: =G33 -> 294.55 | O2: Valor sobra dia 31 - Final do mês
A3: =TODAY() -> 45567 | B3: 45047 | C3: =A3-B3 -> 520 | D3: =C3+K3 -> #VALUE! | E3: =IF(10,K3="ok",0) -> TRUE | F3: Dia 1 | G3: =Setembro!G33+I3 -> -260 | H3: Cartão Transporte | I3: -260 | J3: Dia 1 | K3: ok | L3: =IF(A3=B3,"➜ Hoje","")
A4: =TODAY() -> 45567 | B4: 45048 | C4: =A4-B4 -> 519 | D4: =C4+K4 -> #VALUE! | E4: =IF(10,K4="ok",0) -> TRUE | F4: Dia 2 | G4: =G3+I4 -> -260 | K4: ok | L4: =IF(A4=B4,"➜ Hoje","") | M4: 0.2 | N4: =N2*M4 -> 58.91 | O4: Comemoraçao dia 20
A5: =TODAY() -> 45567 | B5: 45049 | C5: =A5-B5 -> 518 | D5: =C5+K5 -> #VALUE! | E5: =IF(10,K5="ok",0) -> TRUE | F5: Dia 3 | G5: =G4+I5 -> -260 | K5: ok | L5: =IF(A5=B5,"➜ Hoje","") | M5: 0.1 | N5: =N2*M5 -> 29.455 | O5: Reforma/Construção Gatódromo
A6: =TODAY() -> 45567 | B6: 45050 | C6: =A6-B6 -> 517 | D6: =C6+K6 -> #VALUE! | E6: =IF(10,K6="ok",0) -> TRUE | F6: Dia 4 | G6: =G5+I6 -> -440 | H6: Manutenção Guitarra Cort X6 | I6: -180 | J6: Dia 5 | K6: ok | L6: =IF(A6=B6,"➜ Hoje","") | M6: 0.4 | N6: =N2*M6 -> 117.82 | O6: Reforma Cozinha
A7: =TODAY() -> 45567 | B7: 45051 | C7: =A7-B7 -> 516 | D7: =C7+K7 -> #VALUE! | E7: =IF(10,K7="ok",0) -> TRUE | F7: Dia 5 | G7: =G6+I7 -> 700 | H7: Pagamento Recebido Bellocopo | I7: 1140 | J7: Dia 5 | K7: ok | L7: =IF(A7=B7,"➜ Hoje","") | M7: 0.3 | N7: =N2*M7 -> 88.365 | O7: Tirar Carta pra comprar Moto
A8: =TODAY() -> 45567 | B8: 45052 | C8: =A8-B8 -> 515 | D8: =C8+K8 -> #VALUE! | E8: =IF(10,K8="ok",0) -> TRUE | F8: Dia 6 | G8: =G7+I8 -> 2950 | H8: Pagamento Recebido CD Medical Care | I8: 2250 | J8: Dia 6 | K8: ok | L8: =IF(A8=B8,"➜ Hoje","")
A9: =TODAY() -> 45567 | B9: 45053 | C9: =A9-B9 -> 514 | D9: =C9+K9 -> #VALUE! | E9: =IF(10,K9="ok",0) -> TRUE | F9: Dia 7 | G9: =G8+I9 -> 2780 | H9: Ração Gatos Castrados Ultralife | I9: -170 | J9: Dia 6 | K9: ok | L9: =IF(A9=B9,"➜ Hoje","") | M9: Planejamento Aquisições / Projetos
A10: =TODAY() -> 45567 | B10: 45054 | C10: =A10-B10 -> 513 | D10: =C10+K10 -> #VALUE! | E10: =IF(10,K10="ok",0) -> TRUE | F10: Dia 8 | G10: =G9+I10 -> 2741 | H10: Microsoft | I10: -39 | J10: Dia 6 | K10: ok | L10: =IF(A10=B10,"➜ Hoje","")
A11: =TODAY() -> 45567 | B11: 45055 | C11: =A11-B11 -> 512 | D11: =C11+K11 -> #VALUE! | E11: =IF(10,K11="ok",0) -> TRUE | F11: Dia 9 | G11: =G10+I11 -> 2641 | H11: Unhas | I11: -100 | J11: Dia 6 | K11: ok | L11: =IF(A11=B11,"➜ Hoje","") | M11: Data | N11: Valor média | O11: Descrição
A12: =TODAY() -> 45567 | B12: 45056 | C12: =A12-B12 -> 511 | D12: =C12+K12 -> #VALUE! | E12: =IF(10,K12="ok",0) -> TRUE | F12: Dia 10 | G12: =G11+I12 -> 2241 | H12: Psicóloga | I12: -400 | J12: Dia 7 | K12: ok | L12: =IF(A12=B12,"➜ Hoje","") | M12: 45046 | N12: 400 | O12: Depurador de ar (Reforma Cozinha)
A13: =TODAY() -> 45567 | B13: 45057 | C13: =A13-B13 -> 510 | D13: =C13+K13 -> #VALUE! | E13: =IF(10,K13="ok",0) -> TRUE | F13: Dia 11 | G13: =G12+I13 -> 2121 | H13: Energia Elétrica (1/4 pagamento) | I13: -120 | J13: Dia 8 | K13: ok | L13: =IF(A13=B13,"➜ Hoje","") | M13: 44540 | N13: 300 | O13: Revestimento Lume 45x90 Botanico Branco Retif.Azulejo (Reforma Cozinha)
A14: =TODAY() -> 45567 | B14: 45058 | C14: =A14-B14 -> 509 | D14: =C14+K14 -> 509 | E14: =IF(10,K14="ok",0) -> FALSE | F14: Dia 12 | G14: =G13+I14 -> 2011 | H14: Dízimo (1/2 parte) | I14: -110 | J14: Dia 9 | L14: =IF(A14=B14,"➜ Hoje","") | M14: 45041 | N14: 400 | O14: Mesa de Cabeceira Armario modulado Amendola Grafito (Reforma Cozinha)
A15: =TODAY() -> 45567 | B15: 45059 | C15: =A15-B15 -> 508 | D15: =C15+K15 -> #VALUE! | E15: =IF(10,K15="ok",0) -> TRUE | F15: Dia 13 | G15: =G14+I15 -> 1241 | H15: Fatura Cartão Nubank | I15: -770 | J15: Dia 12 | K15: ok | L15: =IF(A15=B15,"➜ Hoje","") | M15: 45046 | N15: 350 | O15: Balcao Madesa Glamy 35cm 1porta (Reforma Cozinha)
A16: =TODAY() -> 45567 | B16: 45060 | C16: =A16-B16 -> 507 | D16: =C16+K16 -> #VALUE! | E16: =IF(10,K16="ok",0) -> TRUE | F16: Dia 14 | G16: =G15+I16 -> 881 | H16: Geladeira (1/11 Parcelas) | I16: -360 | J16: Dia 13 | K16: ok | L16: =IF(A16=B16,"➜ Hoje","")
A17: =TODAY() -> 45567 | B17: 45061 | C17: =A17-B17 -> 506 | D17: =C17+K17 -> #VALUE! | E17: =IF(10,K17="ok",0) -> TRUE | F17: Dia 15 | G17: =G16+I17 -> 801 | H17: Curso Administração | I17: -80 | J17: Dia 13 | K17: ok | L17: =IF(A17=B17,"➜ Hoje","")
A18: =TODAY() -> 45567 | B18: 45062 | C18: =A18-B18 -> 505 | D18: =C18+K18 -> #VALUE! | E18: =IF(10,K18="ok",0) -> TRUE | F18: Dia 16 | G18: =G17+I18 -> 771.9 | H18: Granulado MimiCat (1/2 unidades) | I18: -29.1 | J18: Dia 5 | K18: ok | L18: =IF(A18=B18,"➜ Hoje","") | M18: Planejamento Reposição Dispensa / Compras Mercado
A19: =TODAY() -> 45567 | B19: 45063 | C19: =A19-B19 -> 504 | D19: =C19+K19 -> #VALUE! | E19: =IF(10,K19="ok",0) -> TRUE | F19: Dia 17 | G19: =G18+I19 -> 731.9 | H19: Netflix - Automatico | I19: -40 | J19: Dia 17 | K19: ok | L19: =IF(A19=B19,"➜ Hoje","")
A20: =TODAY() -> 45567 | B20: 45064 | C20: =A20-B20 -> 503 | D20: =C20+K20 -> #VALUE! | E20: =IF(10,K20="ok",0) -> TRUE | F20: Dia 18 | G20: =G19+I20 -> 581.9 | H20: Madeirite plastificado 2200x1100 (1/2) | I20: -150 | J20: Dia 18 | K20: ok | L20: =IF(A20=B20,"➜ Hoje","") | M20: Dia 10 | N20: 500 | O20: Pagamento recebido VA + VR CD Medical Care
A21: =TODAY() -> 45567 | B21: 45065 | C21: =A21-B21 -> 502 | D21: =C21+K21 -> #VALUE! | E21: =IF(10,K21="ok",0) -> TRUE | F21: Dia 19 | G21: =G20+I21 -> 531.9 | H21: Cartão de todos - Automatico | I21: -50 | J21: Dia 19 | K21: ok | L21: =IF(A21=B21,"➜ Hoje","") | M21: Dia 15 | N21: 140 | O21: Pagamento Recebido VA Bellocopo
A22: =TODAY() -> 45567 | B22: 45066 | C22: =A22-B22 -> 501 | D22: =C22+K22 -> #VALUE! | E22: =IF(10,K22="ok",0) -> TRUE | F22: Dia 20 | G22: =G21+I22 -> 1531.9 | H22: Pagamento Recebido Bellocopo | I22: 1000 | J22: Dia 20 | K22: ok | L22: =IF(A22=B22,"➜ Hoje","")
A23: =TODAY() -> 45567 | B23: 45067 | C23: =A23-B23 -> 500 | D23: =C23+K23 -> #VALUE! | E23: =IF(10,K23="ok",0) -> TRUE | F23: Dia 21 | G23: =G22+I23 -> 1516.9 | H23: Nível 6 Mercado Livre - Automatico | I23: -15 | J23: Dia 20 | K23: ok | L23: =IF(A23=B23,"➜ Hoje","")
A24: =TODAY() -> 45567 | B24: 45068 | C24: =A24-B24 -> 499 | D24: =C24+K24 -> #VALUE! | E24: =IF(10,K24="ok",0) -> TRUE | F24: Dia 22 | G24: =G23+I24 -> 1412 | H24: Internet Atranet | I24: -104.9 | J24: Dia 20 | K24: ok | L24: =IF(A24=B24,"➜ Hoje","")
A25: =TODAY() -> 45567 | B25: 45069 | C25: =A25-B25 -> 498 | D25: =C25+K25 -> #VALUE! | E25: =IF(10,K25="ok",0) -> TRUE | F25: Dia 23 | G25: =G24+I25 -> 547 | H25: Fatura Cartão Mercado Livre | I25: -865 | J25: Dia 22 | K25: ok | L25: =IF(A25=B25,"➜ Hoje","")
A26: =TODAY() -> 45567 | B26: 45070 | C26: =A26-B26 -> 497 | D26: =C26+K26 -> 497 | E26: =IF(10,K26="ok",0) -> FALSE | F26: Dia 24 | G26: =G25+I26 -> 437 | H26: Dízimo (2/2 parte) | I26: -110 | J26: Dia 24 | L26: =IF(A26=B26,"➜ Hoje","")
A27: =TODAY() -> 45567 | B27: 45071 | C27: =A27-B27 -> 496 | D27: =C27+K27 -> 496 | E27: =IF(10,K27="ok",0) -> FALSE | F27: Dia 25 | G27: =G26+I27 -> 437 | L27: =IF(A27=B27,"➜ Hoje","") | O27: Areia Gatíssimo (x4 unidades) | P27: -59.6 | Q27: Dia 6
A28: =TODAY() -> 45567 | B28: 45072 | C28: =A28-B28 -> 495 | D28: =C28+K28 -> 495 | E28: =IF(10,K28="ok",0) -> FALSE | F28: Dia 26 | G28: =G27+I28 -> 437 | L28: =IF(A28=B28,"➜ Hoje","") | O28: Alterado para
A29: =TODAY() -> 45567 | B29: 45073 | C29: =A29-B29 -> 494 | D29: =C29+K29 -> 494 | E29: =IF(10,K29="ok",0) -> FALSE | F29: Dia 27 | G29: =G28+I29 -> 392 | H29: Internet Celular Vivo | I29: -45 | J29: Dia 27 | L29: =IF(A29=B29,"➜ Hoje","") | O29: Granulado MimiCat (x3 unidades) | P29: -29.1 | Q29: Dia 5
A30: =TODAY() -> 45567 | B30: 45074 | C30: =A30-B30 -> 493 | D30: =C30+K30 -> #VALUE! | E30: =IF(10,K30="ok",0) -> TRUE | F30: Dia 28 | G30: =G29+I30 -> 312 | H30: Cílios | I30: -80 | J30: Dia 28 | K30: ok | L30: =IF(A30=B30,"➜ Hoje","")
A31: =TODAY() -> 45567 | B31: 45075 | C31: =A31-B31 -> 492 | D31: =C31+K31 -> 492 | E31: =IF(10,K31="ok",0) -> FALSE | F31: Dia 29 | G31: =G30+I31 -> 294.55 | H31: HBO | I31: -17.45 | J31: Dia 29 | L31: =IF(A31=B31,"➜ Hoje","")
A32: =TODAY() -> 45567 | B32: 45076 | C32: =A32-B32 -> 491 | D32: =C32+K32 -> 491 | E32: =IF(10,K32="ok",0) -> FALSE | F32: Dia 30 | G32: =G31+I32 -> 294.55 | L32: =IF(A32=B32,"➜ Hoje","")
A33: =TODAY() -> 45567 | B33: 45077 | C33: =A33-B33 -> 490 | D33: =C33+K33 -> 490 | E33: =IF(10,K33="ok",0) -> FALSE | F33: Dia 31 | G33: =G32+I33 -> 294.55 | L33: =IF(A33=B33,"➜ Hoje","")
M34: Pendencias para pagar
M36: {=F2:K33} -> 0 | N36: Saldo Prévio | O36: Descrição Conta | P36: Valor | Q36: Data vencimento | R36: Pago?
M37: Dia 1 | N37: -260 | O37: Cartão Transporte | P37: -260 | Q37: Dia 1 | R37: ok
M38: Dia 2 | N38: -260 | O38: 0 | P38: 0 | Q38: 0 | R38: ok
M39: Dia 3 | N39: -260 | O39: 0 | P39: 0 | Q39: 0 | R39: ok
M40: Dia 4 | N40: -440 | O40: Manutenção Guitarra Cort X6 | P40: -180 | Q40: Dia 5 | R40: ok
M41: Dia 5 | N41: 700 | O41: Pagamento Recebido Bellocopo | P41: 1140 | Q41: Dia 5 | R41: ok
...

Sheet Junho
A1: Planejamento Mensal Káic e Gabi | I1: Mês: | J1: Junho | M1: Resumo Finalização do Mês | S1: 0
A2: Data hoje formula | B2: Data formula | C2: Formula pgto ok | G2: Saldo Prévio | H2: Descrição Conta | I2: Valor | J2: Data vencimento | K2: Pago? | M2: =F33 -> Dia 31 | N2: =G33 -> 423.55 | O2: Valor sobra dia 31 - Final do mês
A3: =TODAY() -> 45567 | B3: 45078 | C3: =A3-B3 -> 489 | D3: =C3+K3 -> #VALUE! | E3: =IF(10,K3="ok",0) -> TRUE | F3: Dia 1 | G3: =Setembro!G33+I3 -> -260 | H3: Cartão Transporte | I3: -260 | J3: Dia 1 | K3: ok | L3: =IF(A3=B3,"➜ Hoje","")
A4: =TODAY() -> 45567 | B4: 45079 | C4: =A4-B4 -> 488 | D4: =C4+K4 -> #VALUE! | E4: =IF(10,K4="ok",0) -> TRUE | F4: Dia 2 | G4: =G3+I4 -> -260 | K4: ok | L4: =IF(A4=B4,"➜ Hoje","") | M4: 0.2 | N4: =N2*M4 -> 84.71 | O4: Comemoraçao dia 20
A5: =TODAY() -> 45567 | B5: 45080 | C5: =A5-B5 -> 487 | D5: =C5+K5 -> #VALUE! | E5: =IF(10,K5="ok",0) -> TRUE | F5: Dia 3 | G5: =G4+I5 -> -260 | K5: ok | L5: =IF(A5=B5,"➜ Hoje","") | M5: 0.1 | N5: =N2*M5 -> 42.355 | O5: Reforma/Construção Gatódromo
A6: =TODAY() -> 45567 | B6: 45081 | C6: =A6-B6 -> 486 | D6: =C6+K6 -> #VALUE! | E6: =IF(10,K6="ok",0) -> TRUE | F6: Dia 4 | G6: =G5+I6 -> -289.1 | H6: Granulado MimiCat (3 unidades) | I6: -29.1 | J6: Dia 5 | K6: ok | L6: =IF(A6=B6,"➜ Hoje","") | M6: 0.4 | N6: =N2*M6 -> 169.42 | O6: Reforma Cozinha
A7: =TODAY() -> 45567 | B7: 45082 | C7: =A7-B7 -> 485 | D7: =C7+K7 -> #VALUE! | E7: =IF(10,K7="ok",0) -> TRUE | F7: Dia 5 | G7: =G6+I7 -> 850.9 | H7: Pagamento Recebido Bellocopo | I7: 1140 | J7: Dia 5 | K7: ok | L7: =IF(A7=B7,"➜ Hoje","") | M7: 0.3 | N7: =N2*M7 -> 127.065 | O7: Tirar Carta pra comprar Moto
A8: =TODAY() -> 45567 | B8: 45083 | C8: =A8-B8 -> 484 | D8: =C8+K8 -> #VALUE! | E8: =IF(10,K8="ok",0) -> TRUE | F8: Dia 6 | G8: =G7+I8 -> 2750.9 | H8: Pagamento Recebido CD Medical Care | I8: 1900 | J8: Dia 6 | K8: ok | L8: =IF(A8=B8,"➜ Hoje","")
A9: =TODAY() -> 45567 | B9: 45084 | C9: =A9-B9 -> 483 | D9: =C9+K9 -> #VALUE! | E9: =IF(10,K9="ok",0) -> TRUE | F9: Dia 7 | G9: =G8+I9 -> 2580.9 | H9: Ração Gatos Castrados Ultralife | I9: -170 | J9: Dia 6 | K9: ok | L9: =IF(A9=B9,"➜ Hoje","") | M9: Planejamento Aquisições / Projetos
A10: =TODAY() -> 45567 | B10: 45085 | C10: =A10-B10 -> 482 | D10: =C10+K10 -> #VALUE! | E10: =IF(10,K10="ok",0) -> TRUE | F10: Dia 8 | G10: =G9+I10 -> 2541.9 | H10: Microsoft | I10: -39 | J10: Dia 6 | K10: ok | L10: =IF(A10=B10,"➜ Hoje","")
A11: =TODAY() -> 45567 | B11: 45086 | C11: =A11-B11 -> 481 | D11: =C11+K11 -> #VALUE! | E11: =IF(10,K11="ok",0) -> TRUE | F11: Dia 9 | G11: =G10+I11 -> 2441.9 | H11: Unhas | I11: -100 | J11: Dia 6 | K11: ok | L11: =IF(A11=B11,"➜ Hoje","") | M11: Data | N11: Valor média | O11: Descrição
A12: =TODAY() -> 45567 | B12: 45087 | C12: =A12-B12 -> 480 | D12: =C12+K12 -> #VALUE! | E12: =IF(10,K12="ok",0) -> TRUE | F12: Dia 10 | G12: =G11+I12 -> 2041.9 | H12: Psicóloga | I12: -400 | J12: Dia 7 | K12: ok | L12: =IF(A12=B12,"➜ Hoje","") | M12: 45046 | N12: 400 | O12: Depurador de ar (Reforma Cozinha)
A13: =TODAY() -> 45567 | B13: 45088 | C13: =A13-B13 -> 479 | D13: =C13+K13 -> #VALUE! | E13: =IF(10,K13="ok",0) -> TRUE | F13: Dia 11 | G13: =G12+I13 -> 1921.9 | H13: Energia Elétrica (1/4 pagamento) | I13: -120 | J13: Dia 8 | K13: ok | L13: =IF(A13=B13,"➜ Hoje","") | M13: 44540 | N13: 300 | O13: Revestimento Lume 45x90 Botanico Branco Retif.Azulejo (Reforma Cozinha)
A14: =TODAY() -> 45567 | B14: 45089 | C14: =A14-B14 -> 478 | D14: =C14+K14 -> #VALUE! | E14: =IF(10,K14="ok",0) -> TRUE | F14: Dia 12 | G14: =G13+I14 -> 1811.9 | H14: Dízimo (1/2 parte) | I14: -110 | J14: Dia 9 | K14: ok | L14: =IF(A14=B14,"➜ Hoje","") | M14: 45041 | N14: 400 | O14: Mesa de Cabeceira Armario modulado Amendola Grafito (Reforma Cozinha)
A15: =TODAY() -> 45567 | B15: 45090 | C15: =A15-B15 -> 477 | D15: =C15+K15 -> #VALUE! | E15: =IF(10,K15="ok",0) -> TRUE | F15: Dia 13 | G15: =G14+I15 -> 1341.9 | H15: Fatura Cartão Nubank | I15: -470 | J15: Dia 12 | K15: ok | L15: =IF(A15=B15,"➜ Hoje","") | M15: 45046 | N15: 350 | O15: Balcao Madesa Glamy 35cm 1porta (Reforma Cozinha)
A16: =TODAY() -> 45567 | B16: 45091 | C16: =A16-B16 -> 476 | D16: =C16+K16 -> #VALUE! | E16: =IF(10,K16="ok",0) -> TRUE | F16: Dia 14 | G16: =G15+I16 -> 981.9 | H16: Geladeira (2/11 Parcelas) | I16: -360 | J16: Dia 13 | K16: ok | L16: =IF(A16=B16,"➜ Hoje","")
A17: =TODAY() -> 45567 | B17: 45092 | C17: =A17-B17 -> 475 | D17: =C17+K17 -> #VALUE! | E17: =IF(10,K17="ok",0) -> TRUE | F17: Dia 15 | G17: =G16+I17 -> 901.9 | H17: Curso Administração | I17: -80 | J17: Dia 13 | K17: ok | L17: =IF(A17=B17,"➜ Hoje","")
A18: =TODAY() -> 45567 | B18: 45093 | C18: =A18-B18 -> 474 | D18: =C18+K18 -> #VALUE! | E18: =IF(10,K18="ok",0) -> TRUE | F18: Dia 16 | G18: =G17+I18 -> 901.9 | K18: ok | L18: =IF(A18=B18,"➜ Hoje","") | M18: Planejamento Reposição Dispensa / Compras Mercado
A19: =TODAY() -> 45567 | B19: 45094 | C19: =A19-B19 -> 473 | D19: =C19+K19 -> #VALUE! | E19: =IF(10,K19="ok",0) -> TRUE | F19: Dia 17 | G19: =G18+I19 -> 861.9 | H19: Netflix - Automatico | I19: -40 | J19: Dia 17 | K19: ok | L19: =IF(A19=B19,"➜ Hoje","")
A20: =TODAY() -> 45567 | B20: 45095 | C20: =A20-B20 -> 472 | D20: =C20+K20 -> #VALUE! | E20: =IF(10,K20="ok",0) -> TRUE | F20: Dia 18 | G20: =G19+I20 -> 711.9 | H20: Madeirite plastificado 2200x1100 (2/2) | I20: -150 | J20: Dia 18 | K20: ok | L20: =IF(A20=B20,"➜ Hoje","") | M20: Dia 10 | N20: 500 | O20: Pagamento recebido VA + VR CD Medical Care
A21: =TODAY() -> 45567 | B21: 45096 | C21: =A21-B21 -> 471 | D21: =C21+K21 -> #VALUE! | E21: =IF(10,K21="ok",0) -> TRUE | F21: Dia 19 | G21: =G20+I21 -> 661.9 | H21: Cartão de todos - Automatico | I21: -50 | J21: Dia 19 | K21: ok | L21: =IF(A21=B21,"➜ Hoje","") | M21: Dia 15 | N21: 140 | O21: Pagamento Recebido VA Bellocopo
A22: =TODAY() -> 45567 | B22: 45097 | C22: =A22-B22 -> 470 | D22: =C22+K22 -> #VALUE! | E22: =IF(10,K22="ok",0) -> TRUE | F22: Dia 20 | G22: =G21+I22 -> 1661.9 | H22: Pagamento Recebido Bellocopo | I22: 1000 | J22: Dia 20 | K22: ok | L22: =IF(A22=B22,"➜ Hoje","")
A23: =TODAY() -> 45567 | B23: 45098 | C23: =A23-B23 -> 469 | D23: =C23+K23 -> #VALUE! | E23: =IF(10,K23="ok",0) -> TRUE | F23: Dia 21 | G23: =G22+I23 -> 1646.9 | H23: Nível 6 Mercado Livre - Automatico | I23: -15 | J23: Dia 20 | K23: ok | L23: =IF(A23=B23,"➜ Hoje","")
A24: =TODAY() -> 45567 | B24: 45099 | C24: =A24-B24 -> 468 | D24: =C24+K24 -> #VALUE! | E24: =IF(10,K24="ok",0) -> TRUE | F24: Dia 22 | G24: =G23+I24 -> 1542 | H24: Internet Atranet | I24: -104.9 | J24: Dia 20 | K24: ok | L24: =IF(A24=B24,"➜ Hoje","")
A25: =TODAY() -> 45567 | B25: 45100 | C25: =A25-B25 -> 467 | D25: =C25+K25 -> #VALUE! | E25: =IF(10,K25="ok",0) -> TRUE | F25: Dia 23 | G25: =G24+I25 -> 676 | H25: Fatura Cartão Mercado Livre | I25: -866 | J25: Dia 22 | K25: ok | L25: =IF(A25=B25,"➜ Hoje","")
A26: =TODAY() -> 45567 | B26: 45101 | C26: =A26-B26 -> 466 | D26: =C26+K26 -> #VALUE! | E26: =IF(10,K26="ok",0) -> TRUE | F26: Dia 24 | G26: =G25+I26 -> 566 | H26: Dízimo (2/2 parte) | I26: -110 | J26: Dia 24 | K26: ok | L26: =IF(A26=B26,"➜ Hoje","")
A27: =TODAY() -> 45567 | B27: 45102 | C27: =A27-B27 -> 465 | D27: =C27+K27 -> #VALUE! | E27: =IF(10,K27="ok",0) -> TRUE | F27: Dia 25 | G27: =G26+I27 -> 566 | K27: ok | L27: =IF(A27=B27,"➜ Hoje","")
A28: =TODAY() -> 45567 | B28: 45103 | C28: =A28-B28 -> 464 | D28: =C28+K28 -> #VALUE! | E28: =IF(10,K28="ok",0) -> TRUE | F28: Dia 26 | G28: =G27+I28 -> 566 | K28: ok | L28: =IF(A28=B28,"➜ Hoje","")
A29: =TODAY() -> 45567 | B29: 45104 | C29: =A29-B29 -> 463 | D29: =C29+K29 -> #VALUE! | E29: =IF(10,K29="ok",0) -> TRUE | F29: Dia 27 | G29: =G28+I29 -> 521 | H29: Internet Celular Vivo | I29: -45 | J29: Dia 27 | K29: ok | L29: =IF(A29=B29,"➜ Hoje","")
A30: =TODAY() -> 45567 | B30: 45105 | C30: =A30-B30 -> 462 | D30: =C30+K30 -> #VALUE! | E30: =IF(10,K30="ok",0) -> TRUE | F30: Dia 28 | G30: =G29+I30 -> 441 | H30: Cílios | I30: -80 | J30: Dia 28 | K30: ok | L30: =IF(A30=B30,"➜ Hoje","")
A31: =TODAY() -> 45567 | B31: 45106 | C31: =A31-B31 -> 461 | D31: =C31+K31 -> #VALUE! | E31: =IF(10,K31="ok",0) -> TRUE | F31: Dia 29 | G31: =G30+I31 -> 423.55 | H31: HBO | I31: -17.45 | J31: Dia 29 | K31: ok | L31: =IF(A31=B31,"➜ Hoje","")
A32: =TODAY() -> 45567 | B32: 45107 | C32: =A32-B32 -> 460 | D32: =C32+K32 -> #VALUE! | E32: =IF(10,K32="ok",0) -> TRUE | F32: Dia 30 | G32: =G31+I32 -> 423.55 | K32: ok | L32: =IF(A32=B32,"➜ Hoje","")
A33: =TODAY() -> 45567 | B33: 45107 | C33: =A33-B33 -> 460 | D33: =C33+K33 -> #VALUE! | E33: =IF(10,K33="ok",0) -> TRUE | F33: Dia 31 | G33: =G32+I33 -> 423.55 | K33: ok | L33: =IF(A33=B33,"➜ Hoje","")
M34: Pendencias para pagar
M36: {=F2:K33} -> 0 | N36: Saldo Prévio | O36: Descrição Conta | P36: Valor | Q36: Data vencimento | R36: Pago?
M37: Dia 1 | N37: -260 | O37: Cartão Transporte | P37: -260 | Q37: Dia 1 | R37: ok
M38: Dia 2 | N38: -260 | O38: 0 | P38: 0 | Q38: 0 | R38: ok
M39: Dia 3 | N39: -260 | O39: 0 | P39: 0 | Q39: 0 | R39: ok
M40: Dia 4 | N40: -289.1 | O40: Granulado MimiCat (3 unidades) | P40: -29.1 | Q40: Dia 5 | R40: ok
M41: Dia 5 | N41: 850.9 | O41: Pagamento Recebido Bellocopo | P41: 1140 | Q41: Dia 5 | R41: ok
...

Sheet Julho
A1: Planejamento Mensal Káic e Gabi | I1: Mês: | J1: Julho | M1: Resumo Finalização do Mês | S1: 0
A2: Data hoje formula | B2: Data formula | C2: Formula pgto ok | G2: Saldo Prévio | H2: Descrição Conta | I2: Valor | J2: Data vencimento | K2: Pago? | M2: =F33 -> Dia 31 | N2: =G33 -> -63.35 | O2: Valor sobra dia 31 - Final do mês
A3: =TODAY() -> 45567 | B3: 45108 | C3: =A3-B3 -> 459 | D3: =C3+K3 -> #VALUE! | E3: =IF(10,K3="ok",0) -> TRUE | F3: Dia 1 | G3: 0 | H3: Cartão Transporte | I3: 0 | J3: Dia 1 | K3: ok | L3: =IF(A3=B3,"➜ Hoje","")
A4: =TODAY() -> 45567 | B4: 45109 | C4: =A4-B4 -> 458 | D4: =C4+K4 -> #VALUE! | E4: =IF(10,K4="ok",0) -> TRUE | F4: Dia 2 | G4: =G3+I4 -> 0 | K4: ok | L4: =IF(A4=B4,"➜ Hoje","") | M4: 0.2 | N4: =N2*M4 -> -12.67 | O4: Comemoraçao dia 20
A5: =TODAY() -> 45567 | B5: 45110 | C5: =A5-B5 -> 457 | D5: =C5+K5 -> #VALUE! | E5: =IF(10,K5="ok",0) -> TRUE | F5: Dia 3 | G5: =G4+I5 -> 0 | K5: ok | L5: =IF(A5=B5,"➜ Hoje","") | M5: 0.1 | N5: =N2*M5 -> -6.335 | O5: Reforma/Construção Gatódromo
A6: =TODAY() -> 45567 | B6: 45111 | C6: =A6-B6 -> 456 | D6: =C6+K6 -> #VALUE! | E6: =IF(10,K6="ok",0) -> TRUE | F6: Dia 4 | G6: =G5+I6 -> 0 | I6: 0 | J6: Dia 5 | K6: ok | L6: =IF(A6=B6,"➜ Hoje","") | M6: 0.4 | N6: =N2*M6 -> -25.34 | O6: Reforma Cozinha
A7: =TODAY() -> 45567 | B7: 45112 | C7: =A7-B7 -> 455 | D7: =C7+K7 -> #VALUE! | E7: =IF(10,K7="ok",0) -> TRUE | F7: Dia 5 | G7: =G6+I7 -> 1140 | H7: Pagamento Recebido Bellocopo | I7: 1140 | J7: Dia 5 | K7: ok | L7: =IF(A7=B7,"➜ Hoje","") | M7: 0.3 | N7: =N2*M7 -> -19.005 | O7: Tirar Carta pra comprar Moto
A8: =TODAY() -> 45567 | B8: 45113 | C8: =A8-B8 -> 454 | D8: =C8+K8 -> #VALUE! | E8: =IF(10,K8="ok",0) -> TRUE | F8: Dia 6 | G8: =G7+I8 -> 1140 | I8: 0 | J8: Dia 6 | K8: ok | L8: =IF(A8=B8,"➜ Hoje","")
A9: =TODAY() -> 45567 | B9: 45114 | C9: =A9-B9 -> 453 | D9: =C9+K9 -> #VALUE! | E9: =IF(10,K9="ok",0) -> TRUE | F9: Dia 7 | G9: =G8+I9 -> 970 | H9: Ração Gatos Castrados Ultralife | I9: -170 | J9: Dia 6 | K9: ok | L9: =IF(A9=B9,"➜ Hoje","") | M9: Planejamento Aquisições / Projetos
A10: =TODAY() -> 45567 | B10: 45115 | C10: =A10-B10 -> 452 | D10: =C10+K10 -> #VALUE! | E10: =IF(10,K10="ok",0) -> TRUE | F10: Dia 8 | G10: =G9+I10 -> 931 | H10: Microsoft | I10: -39 | J10: Dia 6 | K10: ok | L10: =IF(A10=B10,"➜ Hoje","")
A11: =TODAY() -> 45567 | B11: 45116 | C11: =A11-B11 -> 451 | D11: =C11+K11 -> #VALUE! | E11: =IF(10,K11="ok",0) -> TRUE | F11: Dia 9 | G11: =G10+I11 -> 831 | H11: Unhas | I11: -100 | J11: Dia 6 | K11: ok | L11: =IF(A11=B11,"➜ Hoje","") | M11: Data | N11: Valor média | O11: Descrição
A12: =TODAY() -> 45567 | B12: 45117 | C12: =A12-B12 -> 450 | D12: =C12+K12 -> #VALUE! | E12: =IF(10,K12="ok",0) -> TRUE | F12: Dia 10 | G12: =G11+I12 -> 691 | H12: Psicóloga (Quinzenal) | I12: -140 | J12: Dia 7 | K12: ok | L12: =IF(A12=B12,"➜ Hoje","") | M12: 45046 | N12: 400 | O12: Depurador de ar (Reforma Cozinha)
A13: =TODAY() -> 45567 | B13: 45118 | C13: =A13-B13 -> 449 | D13: =C13+K13 -> #VALUE! | E13: =IF(10,K13="ok",0) -> TRUE | F13: Dia 11 | G13: =G12+I13 -> 571 | H13: Energia Elétrica (1/4 pagamento) | I13: -120 | J13: Dia 8 | K13: ok | L13: =IF(A13=B13,"➜ Hoje","") | M13: 44540 | N13: 300 | O13: Revestimento Lume 45x90 Botanico Branco Retif.Azulejo (Reforma Cozinha)
A14: =TODAY() -> 45567 | B14: 45119 | C14: =A14-B14 -> 448 | D14: =C14+K14 -> #VALUE! | E14: =IF(10,K14="ok",0) -> TRUE | F14: Dia 12 | G14: =G13+I14 -> 461 | H14: Dízimo (1/2 parte) | I14: -110 | J14: Dia 9 | K14: ok | L14: =IF(A14=B14,"➜ Hoje","") | M14: 45041 | N14: 400 | O14: Mesa de Cabeceira Armario modulado Amendola Grafito (Reforma Cozinha)
A15: =TODAY() -> 45567 | B15: 45120 | C15: =A15-B15 -> 447 | D15: =C15+K15 -> #VALUE! | E15: =IF(10,K15="ok",0) -> TRUE | F15: Dia 13 | G15: =G14+I15 -> 461 | H15: Fatura Cartão Nubank | I15: 0 | J15: Dia 12 | K15: ok | L15: =IF(A15=B15,"➜ Hoje","") | M15: 45046 | N15: 350 | O15: Balcao Madesa Glamy 35cm 1porta (Reforma Cozinha)
A16: =TODAY() -> 45567 | B16: 45121 | C16: =A16-B16 -> 446 | D16: =C16+K16 -> #VALUE! | E16: =IF(10,K16="ok",0) -> TRUE | F16: Dia 14 | G16: =G15+I16 -> 101 | H16: Geladeira (3/11 Parcelas) | I16: -360 | J16: Dia 13 | K16: ok | L16: =IF(A16=B16,"➜ Hoje","")
A17: =TODAY() -> 45567 | B17: 45122 | C17: =A17-B17 -> 445 | D17: =C17+K17 -> #VALUE! | E17: =IF(10,K17="ok",0) -> TRUE | F17: Dia 15 | G17: =G16+I17 -> 21 | H17: Curso Administração | I17: -80 | J17: Dia 13 | K17: ok | L17: =IF(A17=B17,"➜ Hoje","")
A18: =TODAY() -> 45567 | B18: 45123 | C18: =A18-B18 -> 444 | D18: =C18+K18 -> #VALUE! | E18: =IF(10,K18="ok",0) -> TRUE | F18: Dia 16 | G18: =G17+I18 -> 21 | K18: ok | L18: =IF(A18=B18,"➜ Hoje","") | M18: Planejamento Reposição Dispensa / Compras Mercado
A19: =TODAY() -> 45567 | B19: 45124 | C19: =A19-B19 -> 443 | D19: =C19+K19 -> #VALUE! | E19: =IF(10,K19="ok",0) -> TRUE | F19: Dia 17 | G19: =G18+I19 -> -19 | H19: Netflix - Automatico | I19: -40 | J19: Dia 17 | K19: ok | L19: =IF(A19=B19,"➜ Hoje","")
A20: =TODAY() -> 45567 | B20: 45125 | C20: =A20-B20 -> 442 | D20: =C20+K20 -> #VALUE! | E20: =IF(10,K20="ok",0) -> TRUE | F20: Dia 18 | G20: =G19+I20 -> -19 | I20: 0 | J20: Dia 18 | K20: ok | L20: =IF(A20=B20,"➜ Hoje","")
A21: =TODAY() -> 45567 | B21: 45126 | C21: =A21-B21 -> 441 | D21: =C21+K21 -> #VALUE! | E21: =IF(10,K21="ok",0) -> TRUE | F21: Dia 19 | G21: =G20+I21 -> -69 | H21: Cartão de todos - Automatico | I21: -50 | J21: Dia 19 | K21: ok | L21: =IF(A21=B21,"➜ Hoje","") | M21: Dia 15 | N21: 140 | O21: Pagamento Recebido VA Bellocopo
A22: =TODAY() -> 45567 | B22: 45127 | C22: =A22-B22 -> 440 | D22: =C22+K22 -> #VALUE! | E22: =IF(10,K22="ok",0) -> TRUE | F22: Dia 20 | G22: =G21+I22 -> 931 | H22: Pagamento Recebido Bellocopo | I22: 1000 | J22: Dia 20 | K22: ok | L22: =IF(A22=B22,"➜ Hoje","")
A23: =TODAY() -> 45567 | B23: 45128 | C23: =A23-B23 -> 439 | D23: =C23+K23 -> #VALUE! | E23: =IF(10,K23="ok",0) -> TRUE | F23: Dia 21 | G23: =G22+I23 -> 916 | H23: Nível 6 Mercado Livre - Automatico | I23: -15 | J23: Dia 20 | K23: ok | L23: =IF(A23=B23,"➜ Hoje","")
A24: =TODAY() -> 45567 | B24: 45129 | C24: =A24-B24 -> 438 | D24: =C24+K24 -> #VALUE! | E24: =IF(10,K24="ok",0) -> TRUE | F24: Dia 22 | G24: =G23+I24 -> 811.1 | H24: Internet Atranet | I24: -104.9 | J24: Dia 20 | K24: ok | L24: =IF(A24=B24,"➜ Hoje","")
A25: =TODAY() -> 45567 | B25: 45130 | C25: =A25-B25 -> 437 | D25: =C25+K25 -> #VALUE! | E25: =IF(10,K25="ok",0) -> TRUE | F25: Dia 23 | G25: =G24+I25 -> 189.1 | H25: Fatura Cartão Mercado Livre | I25: -622 | J25: Dia 22 | K25: ok | L25: =IF(A25=B25,"➜ Hoje","")
A26: =TODAY() -> 45567 | B26: 45131 | C26: =A26-B26 -> 436 | D26: =C26+K26 -> #VALUE! | E26: =IF(10,K26="ok",0) -> TRUE | F26: Dia 24 | G26: =G25+I26 -> 79.1 | H26: Dízimo (2/2 parte) | I26: -110 | J26: Dia 24 | K26: ok | L26: =IF(A26=B26,"➜ Hoje","")
A27: =TODAY() -> 45567 | B27: 45132 | C27: =A27-B27 -> 435 | D27: =C27+K27 -> #VALUE! | E27: =IF(10,K27="ok",0) -> TRUE | F27: Dia 25 | G27: =G26+I27 -> 79.1 | K27: ok | L27: =IF(A27=B27,"➜ Hoje","")
A28: =TODAY() -> 45567 | B28: 45133 | C28: =A28-B28 -> 434 | D28: =C28+K28 -> #VALUE! | E28: =IF(10,K28="ok",0) -> TRUE | F28: Dia 26 | G28: =G27+I28 -> 79.1 | K28: ok | L28: =IF(A28=B28,"➜ Hoje","")
A29: =TODAY() -> 45567 | B29: 45134 | C29: =A29-B29 -> 433 | D29: =C29+K29 -> #VALUE! | E29: =IF(10,K29="ok",0) -> TRUE | F29: Dia 27 | G29: =G28+I29 -> 34.1 | H29: Internet Celular Vivo | I29: -45 | J29: Dia 27 | K29: ok | L29: =IF(A29=B29,"➜ Hoje","")
A30: =TODAY() -> 45567 | B30: 45135 | C30: =A30-B30 -> 432 | D30: =C30+K30 -> #VALUE! | E30: =IF(10,K30="ok",0) -> TRUE | F30: Dia 28 | G30: =G29+I30 -> -45.9 | H30: Cílios | I30: -80 | J30: Dia 28 | K30: ok | L30: =IF(A30=B30,"➜ Hoje","")
A31: =TODAY() -> 45567 | B31: 45136 | C31: =A31-B31 -> 431 | D31: =C31+K31 -> #VALUE! | E31: =IF(10,K31="ok",0) -> TRUE | F31: Dia 29 | G31: =G30+I31 -> -63.35 | H31: HBO | I31: -17.45 | J31: Dia 29 | K31: ok | L31: =IF(A31=B31,"➜ Hoje","")
A32: =TODAY() -> 45567 | B32: 45137 | C32: =A32-B32 -> 430 | D32: =C32+K32 -> #VALUE! | E32: =IF(10,K32="ok",0) -> TRUE | F32: Dia 30 | G32: =G31+I32 -> -63.35 | K32: ok | L32: =IF(A32=B32,"➜ Hoje","")
A33: =TODAY() -> 45567 | B33: 45138 | C33: =A33-B33 -> 429 | D33: =C33+K33 -> #VALUE! | E33: =IF(10,K33="ok",0) -> TRUE | F33: Dia 31 | G33: =G32+I33 -> -63.35 | K33: ok | L33: =IF(A33=B33,"➜ Hoje","")
M34: Pendencias para pagar
M36: {=F2:K33} -> 0 | N36: Saldo Prévio | O36: Descrição Conta | P36: Valor | Q36: Data vencimento | R36: Pago?
M37: Dia 1 | N37: 0 | O37: Cartão Transporte | P37: 0 | Q37: Dia 1 | R37: ok
M38: Dia 2 | N38: 0 | O38: 0 | P38: 0 | Q38: 0 | R38: ok
M39: Dia 3 | N39: 0 | O39: 0 | P39: 0 | Q39: 0 | R39: ok
M40: Dia 4 | N40: 0 | O40: 0 | P40: 0 | Q40: Dia 5 | R40: ok
M41: Dia 5 | N41: 1140 | O41: Pagamento Recebido Bellocopo | P41: 1140 | Q41: Dia 5 | R41: ok
...

Sheet Outubro 2024
A1: Planejamento Mensal Káic e Gabi | I1: Mês: | J1: Outubro | M1: Resumo Finalização do Mês | S1: 0
A2: Data hoje formula | B2: Data formula | C2: Formula pgto ok | G2: Saldo Prévio | H2: Descrição Conta | I2: Valor | J2: Data vencimento | K2: Pago? | M2: =F33 -> Dia 31 | N2: =G33 -> -701.32 | O2: Valor sobra dia 31 - Final do mês
A3: =TODAY() -> 45567 | B3: 45566 | C3: =A3-B3 -> 1 | D3: =C3+K3 -> #VALUE! | E3: =IF(10,K3="ok",0) -> TRUE | F3: Dia 1 | G3: =Setembro!G33+I3-13 -> -40.99 | H3: Nível 6 Mercado Livre - Automatico | I3: -27.99 | J3: Dia 1 | K3: OK | L3: =IF(A3=B3,"➜ Hoje","")
A4: =TODAY() -> 45567 | B4: =B3+1 -> 45567 | C4: =A4-B4 -> 0 | D4: =C4+K4 -> #VALUE! | E4: =IF(10,K4="ok",0) -> TRUE | F4: Dia 2 | G4: =G3+I4 -> 537.92 | H4: Pagamento PLR | I4: 578.91 | J4: Dia 1 | K4: OK | L4: =IF(A4=B4,"➜ Hoje","") -> ➜ Hoje | M4: 0.2 | N4: =IF($N$2*M4<=0,"Em vermelho",$N$2*M4) -> Em vermelho | O4: Comemoraçao dia 20
A5: =TODAY() -> 45567 | B5: =B4+1 -> 45568 | C5: =A5-B5 -> -1 | D5: =C5+K5 -> -1 | E5: =IF(10,K5="ok",0) -> FALSE | F5: Dia 3 | G5: =G4+I5 -> 537.92 | L5: =IF(A5=B5,"➜ Hoje","") | M5: 0.1 | N5: =IF($N$2*M5<=0,"Em vermelho",$N$2*M5) -> Em vermelho | O5: Reforma Casa
A6: =TODAY() -> 45567 | B6: =B5+1 -> 45569 | C6: =A6-B6 -> -2 | D6: =C6+K6 -> -2 | E6: =IF(10,K6="ok",0) -> FALSE | F6: Dia 4 | G6: =G5+I6 -> 515.92 | H6: Granulado Madeira (10kg) | I6: -22 | J6: Dia 5 | L6: =IF(A6=B6,"➜ Hoje","") | M6: 0.4 | N6: =IF($N$2*M6<=0,"Em vermelho",$N$2*M6) -> Em vermelho | O6: Tirar Carta A+B
A7: =TODAY() -> 45567 | B7: =B6+1 -> 45570 | C7: =A7-B7 -> -3 | D7: =C7+K7 -> -3 | E7: =IF(10,K7="ok",0) -> FALSE | F7: Dia 5 | G7: =G6+I7 -> 1915.92 | H7: Pagamento Recebido Bellocopo | I7: 1400 | J7: Dia 5 | L7: =IF(A7=B7,"➜ Hoje","") | M7: 0.3 | N7: =IF($N$2*M7<=0,"Em vermelho",$N$2*M7) -> Em vermelho | O7: Novas Alianças
A8: =TODAY() -> 45567 | B8: =B7+1 -> 45571 | C8: =A8-B8 -> -4 | D8: =C8+K8 -> -4 | E8: =IF(10,K8="ok",0) -> FALSE | F8: Dia 6 | G8: =G7+I8 -> 748.69 | H8: Fatura Cartão Mercado Livre | I8: =-1206.93+39.7 -> -1167.23 | J8: Dia 5 | L8: =IF(A8=B8,"➜ Hoje","")
A9: =TODAY() -> 45567 | B9: =B8+1 -> 45572 | C9: =A9-B9 -> -5 | D9: =C9+K9 -> -5 | E9: =IF(10,K9="ok",0) -> FALSE | F9: Dia 7 | G9: =G8+I9 -> 148.09 | H9: Parcela Moto | I9: -600.6 | J9: Dia 6 | L9: =IF(A9=B9,"➜ Hoje","") | M9: Planejamento Aquisições / Projetos
A10: =TODAY() -> 45567 | B10: =B9+1 -> 45573 | C10: =A10-B10 -> -6 | D10: =C10+K10 -> -6 | E10: =IF(10,K10="ok",0) -> FALSE | F10: Dia 8 | G10: =G9+I10 -> -9.91 | H10: Ração Gatos Golden Castrados | I10: -158 | J10: Dia 6 | L10: =IF(A10=B10,"➜ Hoje","")
A11: =TODAY() -> 45567 | B11: =B10+1 -> 45574 | C11: =A11-B11 -> -7 | D11: =C11+K11 -> -7 | E11: =IF(10,K11="ok",0) -> FALSE | F11: Dia 9 | G11: =G10+I11 -> -48.91 | H11: Microsoft | I11: -39 | J11: Dia 6 | L11: =IF(A11=B11,"➜ Hoje","") | M11: Data | N11: Valor média | O11: Descrição
A12: =TODAY() -> 45567 | B12: =B11+1 -> 45575 | C12: =A12-B12 -> -8 | D12: =C12+K12 -> -8 | E12: =IF(10,K12="ok",0) -> FALSE | F12: Dia 10 | G12: =G11+I12 -> -79.81 | H12: Netflix - Automatico | I12: -30.9 | J12: Dia 9 | L12: =IF(A12=B12,"➜ Hoje","") | M12: 45046 | N12: 400 | O12: Depurador de ar (Reforma Cozinha)
A13: =TODAY() -> 45567 | B13: =B12+1 -> 45576 | C13: =A13-B13 -> -9 | D13: =C13+K13 -> -9 | E13: =IF(10,K13="ok",0) -> FALSE | F13: Dia 11 | G13: =G12+I13 -> -219.81 | H13: Dízimo (1/2 parte) | I13: -140 | J13: Dia 9 | L13: =IF(A13=B13,"➜ Hoje","") | M13: 44540 | N13: 300 | O13: Revestimento Lume 45x90 Botanico Branco Retif.Azulejo (Reforma Cozinha)
A14: =TODAY() -> 45567 | B14: =B13+1 -> 45577 | C14: =A14-B14 -> -10 | D14: =C14+K14 -> -10 | E14: =IF(10,K14="ok",0) -> FALSE | F14: Dia 12 | G14: =G13+I14 -> -247.59 | H14: Anticoncepcional | I14: -27.78 | J14: Dia 10 | L14: =IF(A14=B14,"➜ Hoje","")
A15: =TODAY() -> 45567 | B15: =B14+1 -> 45578 | C15: =A15-B15 -> -11 | D15: =C15+K15 -> -11 | E15: =IF(10,K15="ok",0) -> FALSE | F15: Dia 13 | G15: =G14+I15 -> -264.08 | H15: SimplyPiano | I15: -16.49 | J15: Dia 12 | L15: =IF(A15=B15,"➜ Hoje","")
A16: =TODAY() -> 45567 | B16: =B15+1 -> 45579 | C16: =A16-B16 -> -12 | D16: =C16+K16 -> -12 | E16: =IF(10,K16="ok",0) -> FALSE | F16: Dia 14 | G16: =G15+I16 -> -264.08 | L16: =IF(A16=B16,"➜ Hoje","")
A17: =TODAY() -> 45567 | B17: =B16+1 -> 45580 | C17: =A17-B17 -> -13 | D17: =C17+K17 -> -13 | E17: =IF(10,K17="ok",0) -> FALSE | F17: Dia 15 | G17: =G16+I17 -> -354.08 | H17: Gasolina Moto | I17: -90 | J17: Dia 15 | L17: =IF(A17=B17,"➜ Hoje","")
A18: =TODAY() -> 45567 | B18: =B17+1 -> 45581 | C18: =A18-B18 -> -14 | D18: =C18+K18 -> -14 | E18: =IF(10,K18="ok",0) -> FALSE | F18: Dia 16 | G18: =G17+I18 -> -393.78 | H18: Curso Aryanne Ativando a Libido | I18: -39.7 | J18: Dia 15 | L18: =IF(A18=B18,"➜ Hoje","") | M18: Planejamento Reposição Dispensa / Compras Mercado
A19: =TODAY() -> 45567 | B19: =B18+1 -> 45582 | C19: =A19-B19 -> -15 | D19: =C19+K19 -> -15 | E19: =IF(10,K19="ok",0) -> FALSE | F19: Dia 17 | G19: =G18+I19 -> -393.78 | L19: =IF(A19=B19,"➜ Hoje","")
A20: =TODAY() -> 45567 | B20: =B19+1 -> 45583 | C20: =A20-B20 -> -16 | D20: =C20+K20 -> -16 | E20: =IF(10,K20="ok",0) -> FALSE | F20: Dia 18 | G20: =G19+I20 -> 806.22 | H20: Pagamento Recebido Bellocopo | I20: 1200 | J20: Dia 20 | L20: =IF(A20=B20,"➜ Hoje","") | M20: Dia 15 | N20: 210 | O20: Pagamento Recebido VA Bellocopo
A21: =TODAY() -> 45567 | B21: =B20+1 -> 45584 | C21: =A21-B21 -> -17 | D21: =C21+K21 -> -17 | E21: =IF(10,K21="ok",0) -> FALSE | F21: Dia 19 | G21: =G20+I21 -> -148.78 | H21: Fatura Cartão Nubank | I21: -955 | J21: Dia 20 | L21: =IF(A21=B21,"➜ Hoje","")
A22: =TODAY() -> 45567 | B22: =B21+1 -> 45585 | C22: =A22-B22 -> -18 | D22: =C22+K22 -> -18 | E22: =IF(10,K22="ok",0) -> FALSE | F22: Dia 20 | G22: =G21+I22 -> -160.48 | H22: Spotify | I22: -11.7 | J22: Dia 20 | L22: =IF(A22=B22,"➜ Hoje","") | M22: Planejamento Acerto de dividas - prorrogando para mês seguinte
A23: =TODAY() -> 45567 | B23: =B22+1 -> 45586 | C23: =A23-B23 -> -19 | D23: =C23+K23 -> -19 | E23: =IF(10,K23="ok",0) -> FALSE | F23: Dia 21 | G23: =G22+I23 -> -160.48 | L23: =IF(A23=B23,"➜ Hoje","")
A24: =TODAY() -> 45567 | B24: =B23+1 -> 45587 | C24: =A24-B24 -> -20 | D24: =C24+K24 -> -20 | E24: =IF(10,K24="ok",0) -> FALSE | F24: Dia 22 | G24: =G23+I24 -> -260.38 | H24: Internet Atranet | I24: -99.9 | J24: Dia 20 | L24: =IF(A24=B24,"➜ Hoje","") | N24: 35 | O24: Granulado Madeira (10kg)
A25: =TODAY() -> 45567 | B25: =B24+1 -> 45588 | C25: =A25-B25 -> -21 | D25: =C25+K25 -> -21 | E25: =IF(10,K25="ok",0) -> FALSE | F25: Dia 23 | G25: =G24+I25 -> -271.37 | H25: PicsArt Photo | I25: -10.99 | J25: Dia 21 | L25: =IF(A25=B25,"➜ Hoje","") | N25: 158 | O25: Ração Gatos Golden Castrados
A26: =TODAY() -> 45567 | B26: =B25+1 -> 45589 | C26: =A26-B26 -> -22 | D26: =C26+K26 -> -22 | E26: =IF(10,K26="ok",0) -> FALSE | F26: Dia 24 | G26: =G25+I26 -> -271.37 | L26: =IF(A26=B26,"➜ Hoje","") | N26: 99.9 | O26: Internet Atranet
A27: =TODAY() -> 45567 | B27: =B26+1 -> 45590 | C27: =A27-B27 -> -23 | D27: =C27+K27 -> -23 | E27: =IF(10,K27="ok",0) -> FALSE | F27: Dia 25 | G27: =G26+I27 -> -391.37 | H27: Dízimo (2/2 parte) | I27: -120 | J27: Dia 24 | L27: =IF(A27=B27,"➜ Hoje","") | N27: 127.5 | O27: Cílios
A28: =TODAY() -> 45567 | B28: =B27+1 -> 45591 | C28: =A28-B28 -> -24 | D28: =C28+K28 -> -24 | E28: =IF(10,K28="ok",0) -> FALSE | F28: Dia 26 | G28: =G27+I28 -> -511.37 | H28: Energia Elétrica (1/4 pagamento) | I28: -120 | J28: Dia 20 | L28: =IF(A28=B28,"➜ Hoje","") | N28: 27.78 | O28: Anticoncepcional
A29: =TODAY() -> 45567 | B29: =B28+1 -> 45592 | C29: =A29-B29 -> -25 | D29: =C29+K29 -> -25 | E29: =IF(10,K29="ok",0) -> FALSE | F29: Dia 27 | G29: =G28+I29 -> -556.37 | H29: Internet Celular Vivo | I29: -45 | J29: Dia 27 | L29: =IF(A29=B29,"➜ Hoje","")
A30: =TODAY() -> 45567 | B30: =B29+1 -> 45593 | C30: =A30-B30 -> -26 | D30: =C30+K30 -> -26 | E30: =IF(10,K30="ok",0) -> FALSE | F30: Dia 28 | G30: =G29+I30 -> -683.87 | H30: Cílios | I30: -127.5 | J30: Dia 28 | L30: =IF(A30=B30,"➜ Hoje","") | M30: Prorrogar: | N30: =SUM(N24:N29) -> 448.18
A31: =TODAY() -> 45567 | B31: =B30+1 -> 45594 | C31: =A31-B31 -> -27 | D31: =C31+K31 -> -27 | E31: =IF(10,K31="ok",0) -> FALSE | F31: Dia 29 | G31: =G30+I31 -> -701.32 | H31: HBO | I31: -17.45 | J31: Dia 29 | L31: =IF(A31=B31,"➜ Hoje","") | M31: =M2 -> Dia 31 | N31: =N2+N30 -> -253.14 | O31: Valor sobra dia 31 - Final do mês
A32: =TODAY() -> 45567 | B32: =B31+1 -> 45595 | C32: =A32-B32 -> -28 | D32: =C32+K32 -> -28 | E32: =IF(10,K32="ok",0) -> FALSE | F32: Dia 30 | G32: =G31+I32 -> -701.32 | L32: =IF(A32=B32,"➜ Hoje","") | N32: =N30*2 -> 896.36
A33: =TODAY() -> 45567 | B33: 45596 | C33: =A33-B33 -> -29 | D33: =C33+K33 -> -29 | E33: =IF(10,K33="ok",0) -> FALSE | F33: Dia 31 | G33: =G32+I33 -> -701.32 | L33: =IF(A33=B33,"➜ Hoje","") | N33: =N30-N32 -> -448.18
M34: Pendencias para pagar
M36: {=F2:K33} -> 0 | N36: Saldo Prévio | O36: Descrição Conta | P36: Valor | Q36: Data vencimento | R36: Pago?
M37: Dia 1 | N37: -40.99 | O37: Nível 6 Mercado Livre - Automatico | P37: -27.99 | Q37: Dia 1 | R37: OK
M38: Dia 2 | N38: 537.92 | O38: Pagamento PLR | P38: 578.91 | Q38: Dia 1 | R38: OK
M39: Dia 3 | N39: 537.92 | O39: 0 | P39: 0 | Q39: 0 | R39: 0
M40: Dia 4 | N40: 515.92 | O40: Granulado Madeira (10kg) | P40: -22 | Q40: Dia 5 | R40: 0
M41: Dia 5 | N41: 1915.92 | O41: Pagamento Recebido Bellocopo | P41: 1400 | Q41: Dia 5 | R41: 0
...

Sheet Novembro 2024
A1: Planejamento Mensal Káic e Gabi | I1: Mês: | J1: Novembro | M1: Resumo Finalização do Mês | S1: 0
A2: Data hoje formula | B2: Data formula | C2: Formula pgto ok | G2: Saldo Prévio | H2: Descrição Conta | I2: Valor | J2: Data vencimento | K2: Pago? | M2: =F33 -> Dia 31 | N2: =G33 -> 25.05 | O2: Valor sobra dia 31 - Final do mês
A3: =TODAY() -> 45567 | B3: 45597 | C3: =A3-B3 -> -30 | D3: =C3+K3 -> -30 | E3: =IF(10,K3="ok",0) -> FALSE | F3: Dia 1 | G3: ='Outubro 2024'!G33+I3 -> -701.32 | L3: =IF(A3=B3,"➜ Hoje","")
A4: =TODAY() -> 45567 | B4: =B3+1 -> 45598 | C4: =A4-B4 -> -31 | D4: =C4+K4 -> -31 | E4: =IF(10,K4="ok",0) -> FALSE | F4: Dia 2 | G4: =G3+I4 -> -729.31 | H4: Nível 6 Mercado Livre - Automatico | I4: -27.99 | J4: Dia 1 | L4: =IF(A4=B4,"➜ Hoje","") | M4: 0.2 | N4: =IF($N$2*M4<=0,"Em vermelho",$N$2*M4) -> 5.01 | O4: Comemoraçao dia 20
A5: =TODAY() -> 45567 | B5: =B4+1 -> 45599 | C5: =A5-B5 -> -32 | D5: =C5+K5 -> -32 | E5: =IF(10,K5="ok",0) -> FALSE | F5: Dia 3 | G5: =G4+I5 -> -729.31 | L5: =IF(A5=B5,"➜ Hoje","") | M5: 0.1 | N5: =IF($N$2*M5<=0,"Em vermelho",$N$2*M5) -> 2.505 | O5: Reforma Casa
A6: =TODAY() -> 45567 | B6: =B5+1 -> 45600 | C6: =A6-B6 -> -33 | D6: =C6+K6 -> -33 | E6: =IF(10,K6="ok",0) -> FALSE | F6: Dia 4 | G6: =G5+I6 -> -764.31 | H6: Granulado Madeira (10kg) | I6: -35 | J6: Dia 5 | L6: =IF(A6=B6,"➜ Hoje","") | M6: 0.4 | N6: =IF($N$2*M6<=0,"Em vermelho",$N$2*M6) -> 10.02 | O6: Tirar Carta A+B
A7: =TODAY() -> 45567 | B7: =B6+1 -> 45601 | C7: =A7-B7 -> -34 | D7: =C7+K7 -> -34 | E7: =IF(10,K7="ok",0) -> FALSE | F7: Dia 5 | G7: =G6+I7 -> 635.69 | H7: Pagamento Recebido Bellocopo | I7: 1400 | J7: Dia 5 | L7: =IF(A7=B7,"➜ Hoje","") | M7: 0.3 | N7: =IF($N$2*M7<=0,"Em vermelho",$N$2*M7) -> 7.515 | O7: Novas Alianças
A8: =TODAY() -> 45567 | B8: =B7+1 -> 45602 | C8: =A8-B8 -> -35 | D8: =C8+K8 -> -35 | E8: =IF(10,K8="ok",0) -> FALSE | F8: Dia 6 | G8: =G7+I8 -> 555.36 | H8: Fatura Cartão Mercado Pago | I8: =-120.03+39.7 -> -80.33 | J8: Dia 5 | L8: =IF(A8=B8,"➜ Hoje","")
A9: =TODAY() -> 45567 | B9: =B8+1 -> 45603 | C9: =A9-B9 -> -36 | D9: =C9+K9 -> -36 | E9: =IF(10,K9="ok",0) -> FALSE | F9: Dia 7 | G9: =G8+I9 -> -45.24 | H9: Parcela Moto | I9: -600.6 | J9: Dia 6 | L9: =IF(A9=B9,"➜ Hoje","") | M9: Planejamento Aquisições / Projetos
A10: =TODAY() -> 45567 | B10: =B9+1 -> 45604 | C10: =A10-B10 -> -37 | D10: =C10+K10 -> -37 | E10: =IF(10,K10="ok",0) -> FALSE | F10: Dia 8 | G10: =G9+I10 -> -203.24 | H10: Ração Gatos Golden Castrados | I10: -158 | J10: Dia 6 | L10: =IF(A10=B10,"➜ Hoje","")
A11: =TODAY() -> 45567 | B11: =B10+1 -> 45605 | C11: =A11-B11 -> -38 | D11: =C11+K11 -> -38 | E11: =IF(10,K11="ok",0) -> FALSE | F11: Dia 9 | G11: =G10+I11 -> -242.24 | H11: Microsoft | I11: -39 | J11: Dia 6 | L11: =IF(A11=B11,"➜ Hoje","") | M11: Data | N11: Valor média | O11: Descrição
A12: =TODAY() -> 45567 | B12: =B11+1 -> 45606 | C12: =A12-B12 -> -39 | D12: =C12+K12 -> -39 | E12: =IF(10,K12="ok",0) -> FALSE | F12: Dia 10 | G12: =G11+I12 -> -242.24 | L12: =IF(A12=B12,"➜ Hoje","") | M12: 45046 | N12: 400 | O12: Depurador de ar (Reforma Cozinha)
A13: =TODAY() -> 45567 | B13: =B12+1 -> 45607 | C13: =A13-B13 -> -40 | D13: =C13+K13 -> -40 | E13: =IF(10,K13="ok",0) -> FALSE | F13: Dia 11 | G13: =G12+I13 -> -242.24 | L13: =IF(A13=B13,"➜ Hoje","") | M13: 44540 | N13: 300 | O13: Revestimento Lume 45x90 Botanico Branco Retif.Azulejo (Reforma Cozinha)
A14: =TODAY() -> 45567 | B14: =B13+1 -> 45608 | C14: =A14-B14 -> -41 | D14: =C14+K14 -> -41 | E14: =IF(10,K14="ok",0) -> FALSE | F14: Dia 12 | G14: =G13+I14 -> -273.14 | H14: Netflix - Automatico | I14: -30.9 | J14: Dia 9 | L14: =IF(A14=B14,"➜ Hoje","")
A15: =TODAY() -> 45567 | B15: =B14+1 -> 45609 | C15: =A15-B15 -> -42 | D15: =C15+K15 -> -42 | E15: =IF(10,K15="ok",0) -> FALSE | F15: Dia 13 | G15: =G14+I15 -> -413.14 | H15: Dízimo (1/2 parte) | I15: -140 | J15: Dia 9 | L15: =IF(A15=B15,"➜ Hoje","")
A16: =TODAY() -> 45567 | B16: =B15+1 -> 45610 | C16: =A16-B16 -> -43 | D16: =C16+K16 -> -43 | E16: =IF(10,K16="ok",0) -> FALSE | F16: Dia 14 | G16: =G15+I16 -> -440.92 | H16: Anticoncepcional | I16: -27.78 | J16: Dia 10 | L16: =IF(A16=B16,"➜ Hoje","")
A17: =TODAY() -> 45567 | B17: =B16+1 -> 45611 | C17: =A17-B17 -> -44 | D17: =C17+K17 -> -44 | E17: =IF(10,K17="ok",0) -> FALSE | F17: Dia 15 | G17: =G16+I17 -> -457.41 | H17: SimplyPiano | I17: -16.49 | J17: Dia 12 | L17: =IF(A17=B17,"➜ Hoje","")
A18: =TODAY() -> 45567 | B18: =B17+1 -> 45612 | C18: =A18-B18 -> -45 | D18: =C18+K18 -> -45 | E18: =IF(10,K18="ok",0) -> FALSE | F18: Dia 16 | G18: =G17+I18 -> -594.41 | H18: Fatura Cartão Nubank | I18: -137 | J18: Dia 12 | L18: =IF(A18=B18,"➜ Hoje","") | M18: Planejamento Reposição Dispensa / Compras Mercado
A19: =TODAY() -> 45567 | B19: =B18+1 -> 45613 | C19: =A19-B19 -> -46 | D19: =C19+K19 -> -46 | E19: =IF(10,K19="ok",0) -> FALSE | F19: Dia 17 | G19: =G18+I19 -> -634.11 | H19: Curso Aryanne Ativando a Libido | I19: -39.7 | J19: Dia 15 | L19: =IF(A19=B19,"➜ Hoje","")
A20: =TODAY() -> 45567 | B20: =B19+1 -> 45614 | C20: =A20-B20 -> -47 | D20: =C20+K20 -> -47 | E20: =IF(10,K20="ok",0) -> FALSE | F20: Dia 18 | G20: =G19+I20 -> -634.11 | L20: =IF(A20=B20,"➜ Hoje","") | M20: Dia 15 | N20: 210 | O20: Pagamento Recebido VA Bellocopo
A21: =TODAY() -> 45567 | B21: =B20+1 -> 45615 | C21: =A21-B21 -> -48 | D21: =C21+K21 -> -48 | E21: =IF(10,K21="ok",0) -> FALSE | F21: Dia 19 | G21: =G20+I21 -> -634.11 | L21: =IF(A21=B21,"➜ Hoje","")
A22: =TODAY() -> 45567 | B22: =B21+1 -> 45616 | C22: =A22-B22 -> -49 | D22: =C22+K22 -> -49 | E22: =IF(10,K22="ok",0) -> FALSE | F22: Dia 20 | G22: =G21+I22 -> 565.89 | H22: Pagamento Recebido Bellocopo | I22: 1200 | J22: Dia 20 | L22: =IF(A22=B22,"➜ Hoje","") | M22: Planejamento Acerto de dividas - prorrogando para mês seguinte
A23: =TODAY() -> 45567 | B23: =B22+1 -> 45617 | C23: =A23-B23 -> -50 | D23: =C23+K23 -> -50 | E23: =IF(10,K23="ok",0) -> FALSE | F23: Dia 21 | G23: =G22+I23 -> 565.89 | L23: =IF(A23=B23,"➜ Hoje","")
A24: =TODAY() -> 45567 | B24: =B23+1 -> 45618 | C24: =A24-B24 -> -51 | D24: =C24+K24 -> -51 | E24: =IF(10,K24="ok",0) -> FALSE | F24: Dia 22 | G24: =G23+I24 -> 465.99 | H24: Internet Atranet | I24: -99.9 | J24: Dia 20 | L24: =IF(A24=B24,"➜ Hoje","")
A25: =TODAY() -> 45567 | B25: =B24+1 -> 45619 | C25: =A25-B25 -> -52 | D25: =C25+K25 -> -52 | E25: =IF(10,K25="ok",0) -> FALSE | F25: Dia 23 | G25: =G24+I25 -> 455 | H25: PicsArt Photo | I25: -10.99 | J25: Dia 21 | L25: =IF(A25=B25,"➜ Hoje","")
A26: =TODAY() -> 45567 | B26: =B25+1 -> 45620 | C26: =A26-B26 -> -53 | D26: =C26+K26 -> -53 | E26: =IF(10,K26="ok",0) -> FALSE | F26: Dia 24 | G26: =G25+I26 -> 455 | L26: =IF(A26=B26,"➜ Hoje","")
A27: =TODAY() -> 45567 | B27: =B26+1 -> 45621 | C27: =A27-B27 -> -54 | D27: =C27+K27 -> -54 | E27: =IF(10,K27="ok",0) -> FALSE | F27: Dia 25 | G27: =G26+I27 -> 335 | H27: Dízimo (2/2 parte) | I27: -120 | J27: Dia 24 | L27: =IF(A27=B27,"➜ Hoje","")
A28: =TODAY() -> 45567 | B28: =B27+1 -> 45622 | C28: =A28-B28 -> -55 | D28: =C28+K28 -> -55 | E28: =IF(10,K28="ok",0) -> FALSE | F28: Dia 26 | G28: =G27+I28 -> 215 | H28: Energia Elétrica (1/4 pagamento) | I28: -120 | J28: Dia 20 | L28: =IF(A28=B28,"➜ Hoje","")
A29: =TODAY() -> 45567 | B29: =B28+1 -> 45623 | C29: =A29-B29 -> -56 | D29: =C29+K29 -> -56 | E29: =IF(10,K29="ok",0) -> FALSE | F29: Dia 27 | G29: =G28+I29 -> 170 | H29: Internet Celular Vivo | I29: -45 | J29: Dia 27 | L29: =IF(A29=B29,"➜ Hoje","")
A30: =TODAY() -> 45567 | B30: =B29+1 -> 45624 | C30: =A30-B30 -> -57 | D30: =C30+K30 -> -57 | E30: =IF(10,K30="ok",0) -> FALSE | F30: Dia 28 | G30: =G29+I30 -> 42.5 | H30: Cílios | I30: -127.5 | J30: Dia 28 | L30: =IF(A30=B30,"➜ Hoje","") | M30: Prorrogar: | N30: =SUM(N24:N29) -> 0
A31: =TODAY() -> 45567 | B31: =B30+1 -> 45625 | C31: =A31-B31 -> -58 | D31: =C31+K31 -> -58 | E31: =IF(10,K31="ok",0) -> FALSE | F31: Dia 29 | G31: =G30+I31 -> 25.05 | H31: HBO | I31: -17.45 | J31: Dia 29 | L31: =IF(A31=B31,"➜ Hoje","") | M31: =M2 -> Dia 31 | N31: =N2+N30 -> 25.05 | O31: Valor sobra dia 31 - Final do mês
A32: =TODAY() -> 45567 | B32: =B31+1 -> 45626 | C32: =A32-B32 -> -59 | D32: =C32+K32 -> -59 | E32: =IF(10,K32="ok",0) -> FALSE | F32: Dia 30 | G32: =G31+I32 -> 25.05 | L32: =IF(A32=B32,"➜ Hoje","") | N32: =N30*2 -> 0
A33: =TODAY() -> 45567 | B33: 45596 | C33: =A33-B33 -> -29 | D33: =C33+K33 -> -29 | E33: =IF(10,K33="ok",0) -> FALSE | F33: Dia 31 | G33: =G32+I33 -> 25.05 | L33: =IF(A33=B33,"➜ Hoje","") | N33: =N30-N32 -> 0
M34: Pendencias para pagar
M36: {=F2:K33} -> 0 | N36: Saldo Prévio | O36: Descrição Conta | P36: Valor | Q36: Data vencimento | R36: Pago?
M37: Dia 1 | N37: -701.32 | O37: 0 | P37: 0 | Q37: 0 | R37: 0
M38: Dia 2 | N38: -729.31 | O38: Nível 6 Mercado Livre - Automatico | P38: -27.99 | Q38: Dia 1 | R38: 0
M39: Dia 3 | N39: -729.31 | O39: 0 | P39: 0 | Q39: 0 | R39: 0
M40: Dia 4 | N40: -764.31 | O40: Granulado Madeira (10kg) | P40: -35 | Q40: Dia 5 | R40: 0
M41: Dia 5 | N41: 635.69 | O41: Pagamento Recebido Bellocopo | P41: 1400 | Q41: Dia 5 | R41: 0
...

Sheet Dezembro 2024
A1: Planejamento Mensal Káic e Gabi | I1: Mês: | J1: Dezembro | M1: Resumo Finalização do Mês | S1: 0
A2: Data hoje formula | B2: Data formula | C2: Formula pgto ok | G2: Saldo Prévio | H2: Descrição Conta | I2: Valor | J2: Data vencimento | K2: Pago? | M2: =F33 -> Dia 31 | N2: =G33 -> 2899.64 | O2: Valor sobra dia 31 - Final do mês
A3: =TODAY() -> 45567 | B3: 45627 | C3: =A3-B3 -> -60 | D3: =C3+K3 -> -60 | E3: =IF(10,K3="ok",0) -> FALSE | F3: Dia 1 | G3: ='Novembro 2024'!G33+'Novembro 2024'!I3 -> 25.05 | L3: =IF(A3=B3,"➜ Hoje","")
A4: =TODAY() -> 45567 | B4: =B3+1 -> 45628 | C4: =A4-B4 -> -61 | D4: =C4+K4 -> -61 | E4: =IF(10,K4="ok",0) -> FALSE | F4: Dia 2 | G4: =G3+I4 -> -2.94 | H4: Nível 6 Mercado Livre - Automatico | I4: -27.99 | J4: Dia 1 | L4: =IF(A4=B4,"➜ Hoje","") | M4: 0.2 | N4: =IF($N$2*M4<=0,"Em vermelho",$N$2*M4) -> 579.928 | O4: Comemoraçao dia 20
A5: =TODAY() -> 45567 | B5: =B4+1 -> 45629 | C5: =A5-B5 -> -62 | D5: =C5+K5 -> -62 | E5: =IF(10,K5="ok",0) -> FALSE | F5: Dia 3 | G5: =G4+I5 -> -2.94 | L5: =IF(A5=B5,"➜ Hoje","") | M5: 0.1 | N5: =IF($N$2*M5<=0,"Em vermelho",$N$2*M5) -> 289.964 | O5: Reforma Casa
A6: =TODAY() -> 45567 | B6: =B5+1 -> 45630 | C6: =A6-B6 -> -63 | D6: =C6+K6 -> -63 | E6: =IF(10,K6="ok",0) -> FALSE | F6: Dia 4 | G6: =G5+I6 -> -37.94 | H6: Granulado Madeira (10kg) | I6: -35 | J6: Dia 5 | L6: =IF(A6=B6,"➜ Hoje","") | M6: 0.4 | N6: =IF($N$2*M6<=0,"Em vermelho",$N$2*M6) -> 1159.856 | O6: Tirar Carta A+B
A7: =TODAY() -> 45567 | B7: =B6+1 -> 45631 | C7: =A7-B7 -> -64 | D7: =C7+K7 -> -64 | E7: =IF(10,K7="ok",0) -> FALSE | F7: Dia 5 | G7: =G6+I7 -> 1362.06 | H7: Pagamento Recebido Bellocopo | I7: 1400 | J7: Dia 5 | L7: =IF(A7=B7,"➜ Hoje","") | M7: 0.3 | N7: =IF($N$2*M7<=0,"Em vermelho",$N$2*M7) -> 869.892 | O7: Novas Alianças
A8: =TODAY() -> 45567 | B8: =B7+1 -> 45632 | C8: =A8-B8 -> -65 | D8: =C8+K8 -> -65 | E8: =IF(10,K8="ok",0) -> FALSE | F8: Dia 6 | G8: =G7+I8 -> 1351.59 | H8: Fatura Cartão Mercado Livre | I8: =-50.17+39.7 -> -10.47 | J8: Dia 5 | L8: =IF(A8=B8,"➜ Hoje","")
A9: =TODAY() -> 45567 | B9: =B8+1 -> 45633 | C9: =A9-B9 -> -66 | D9: =C9+K9 -> -66 | E9: =IF(10,K9="ok",0) -> FALSE | F9: Dia 7 | G9: =G8+I9 -> 750.99 | H9: Parcela Moto | I9: -600.6 | J9: Dia 6 | L9: =IF(A9=B9,"➜ Hoje","") | M9: Planejamento Aquisições / Projetos
A10: =TODAY() -> 45567 | B10: =B9+1 -> 45634 | C10: =A10-B10 -> -67 | D10: =C10+K10 -> -67 | E10: =IF(10,K10="ok",0) -> FALSE | F10: Dia 8 | G10: =G9+I10 -> 592.99 | H10: Ração Gatos Golden Castrados | I10: -158 | J10: Dia 6 | L10: =IF(A10=B10,"➜ Hoje","")
A11: =TODAY() -> 45567 | B11: =B10+1 -> 45635 | C11: =A11-B11 -> -68 | D11: =C11+K11 -> -68 | E11: =IF(10,K11="ok",0) -> FALSE | F11: Dia 9 | G11: =G10+I11 -> 553.99 | H11: Microsoft | I11: -39 | J11: Dia 6 | L11: =IF(A11=B11,"➜ Hoje","") | M11: Data | N11: Valor média | O11: Descrição
A12: =TODAY() -> 45567 | B12: =B11+1 -> 45636 | C12: =A12-B12 -> -69 | D12: =C12+K12 -> -69 | E12: =IF(10,K12="ok",0) -> FALSE | F12: Dia 10 | G12: =G11+I12 -> 553.99 | L12: =IF(A12=B12,"➜ Hoje","") | M12: 45046 | N12: 400 | O12: Depurador de ar (Reforma Cozinha)
A13: =TODAY() -> 45567 | B13: =B12+1 -> 45637 | C13: =A13-B13 -> -70 | D13: =C13+K13 -> -70 | E13: =IF(10,K13="ok",0) -> FALSE | F13: Dia 11 | G13: =G12+I13 -> 553.99 | L13: =IF(A13=B13,"➜ Hoje","") | M13: 44540 | N13: 300 | O13: Revestimento Lume 45x90 Botanico Branco Retif.Azulejo (Reforma Cozinha)
A14: =TODAY() -> 45567 | B14: =B13+1 -> 45638 | C14: =A14-B14 -> -71 | D14: =C14+K14 -> -71 | E14: =IF(10,K14="ok",0) -> FALSE | F14: Dia 12 | G14: =G13+I14 -> 523.09 | H14: Netflix - Automatico | I14: -30.9 | J14: Dia 9 | L14: =IF(A14=B14,"➜ Hoje","")
A15: =TODAY() -> 45567 | B15: =B14+1 -> 45639 | C15: =A15-B15 -> -72 | D15: =C15+K15 -> -72 | E15: =IF(10,K15="ok",0) -> FALSE | F15: Dia 13 | G15: =G14+I15 -> 383.09 | H15: Dízimo (1/2 parte) | I15: -140 | J15: Dia 9 | L15: =IF(A15=B15,"➜ Hoje","")
A16: =TODAY() -> 45567 | B16: =B15+1 -> 45640 | C16: =A16-B16 -> -73 | D16: =C16+K16 -> -73 | E16: =IF(10,K16="ok",0) -> FALSE | F16: Dia 14 | G16: =G15+I16 -> 355.31 | H16: Anticoncepcional | I16: -27.78 | J16: Dia 10 | L16: =IF(A16=B16,"➜ Hoje","")
A17: =TODAY() -> 45567 | B17: =B16+1 -> 45641 | C17: =A17-B17 -> -74 | D17: =C17+K17 -> -74 | E17: =IF(10,K17="ok",0) -> FALSE | F17: Dia 15 | G17: =G16+I17 -> 338.82 | H17: SimplyPiano | I17: -16.49 | J17: Dia 12 | L17: =IF(A17=B17,"➜ Hoje","")
A18: =TODAY() -> 45567 | B18: =B17+1 -> 45642 | C18: =A18-B18 -> -75 | D18: =C18+K18 -> -75 | E18: =IF(10,K18="ok",0) -> FALSE | F18: Dia 16 | G18: =G17+I18 -> 299.12 | H18: Curso Aryanne Ativando a Libido | I18: -39.7 | J18: Dia 15 | L18: =IF(A18=B18,"➜ Hoje","") | M18: Planejamento Reposição Dispensa / Compras Mercado
A19: =TODAY() -> 45567 | B19: =B18+1 -> 45643 | C19: =A19-B19 -> -76 | D19: =C19+K19 -> -76 | E19: =IF(10,K19="ok",0) -> FALSE | F19: Dia 17 | G19: =G18+I19 -> 299.12 | L19: =IF(A19=B19,"➜ Hoje","")
A20: =TODAY() -> 45567 | B20: =B19+1 -> 45644 | C20: =A20-B20 -> -77 | D20: =C20+K20 -> -77 | E20: =IF(10,K20="ok",0) -> FALSE | F20: Dia 18 | G20: =G19+I20 -> 2299.12 | H20: Acréscimo 13 Salario | I20: 2000 | L20: =IF(A20=B20,"➜ Hoje","") | M20: Dia 15 | N20: 210 | O20: Pagamento Recebido VA Bellocopo
A21: =TODAY() -> 45567 | B21: =B20+1 -> 45645 | C21: =A21-B21 -> -78 | D21: =C21+K21 -> -78 | E21: =IF(10,K21="ok",0) -> FALSE | F21: Dia 19 | G21: =G20+I21 -> 2240.48 | H21: Fatura Cartão Nubank | I21: -58.64 | J21: Dia 12 | L21: =IF(A21=B21,"➜ Hoje","")
A22: =TODAY() -> 45567 | B22: =B21+1 -> 45646 | C22: =A22-B22 -> -79 | D22: =C22+K22 -> -79 | E22: =IF(10,K22="ok",0) -> FALSE | F22: Dia 20 | G22: =G21+I22 -> 3440.48 | H22: Pagamento Recebido Bellocopo | I22: 1200 | J22: Dia 20 | L22: =IF(A22=B22,"➜ Hoje","") | M22: Planejamento Acerto de dividas - prorrogando para mês seguinte
A23: =TODAY() -> 45567 | B23: =B22+1 -> 45647 | C23: =A23-B23 -> -80 | D23: =C23+K23 -> -80 | E23: =IF(10,K23="ok",0) -> FALSE | F23: Dia 21 | G23: =G22+I23 -> 3440.48 | L23: =IF(A23=B23,"➜ Hoje","")
A24: =TODAY() -> 45567 | B24: =B23+1 -> 45648 | C24: =A24-B24 -> -81 | D24: =C24+K24 -> -81 | E24: =IF(10,K24="ok",0) -> FALSE | F24: Dia 22 | G24: =G23+I24 -> 3340.58 | H24: Internet Atranet | I24: -99.9 | J24: Dia 20 | L24: =IF(A24=B24,"➜ Hoje","")
A25: =TODAY() -> 45567 | B25: =B24+1 -> 45649 | C25: =A25-B25 -> -82 | D25: =C25+K25 -> -82 | E25: =IF(10,K25="ok",0) -> FALSE | F25: Dia 23 | G25: =G24+I25 -> 3329.59 | H25: PicsArt Photo | I25: -10.99 | J25: Dia 21 | L25: =IF(A25=B25,"➜ Hoje","")
A26: =TODAY() -> 45567 | B26: =B25+1 -> 45650 | C26: =A26-B26 -> -83 | D26: =C26+K26 -> -83 | E26: =IF(10,K26="ok",0) -> FALSE | F26: Dia 24 | G26: =G25+I26 -> 3329.59 | L26: =IF(A26=B26,"➜ Hoje","")
A27: =TODAY() -> 45567 | B27: =B26+1 -> 45651 | C27: =A27-B27 -> -84 | D27: =C27+K27 -> -84 | E27: =IF(10,K27="ok",0) -> FALSE | F27: Dia 25 | G27: =G26+I27 -> 3209.59 | H27: Dízimo (2/2 parte) | I27: -120 | J27: Dia 24 | L27: =IF(A27=B27,"➜ Hoje","")
